<mujoco model="the_six">
  <option iterations="50" timestep="0.001" solver="PGS" gravity="0 0 -9.81" />

  <compiler angle="radian" meshdir="./" eulerseq="zyx" autolimits="true" />

  <default>
    <joint limited="true" actuatorfrclimited="true" damping="0" frictionloss="0" />
    <position ctrllimited="true" forcelimited="true" gear="1" />
    <default class="hand_joint">
      <position kp="10" kv="0.01" />
    </default>
    <geom condim="3" contype="1" conaffinity="15" friction="0.8 0.2 0.2" solref="0.001 2" />
    <default class="link_geom">
      <geom material="link_geom" contype="1" conaffinity="0" />
    </default>
  </default>

  <asset>
    <texture builtin="checker" height="512" name="texplane" rgb1=".2 .3 .4" rgb2=".1 0.15 0.2"
      type="2d" width="512" />
    <material name="floorplane" reflectance="0.3" texrepeat="1 1" texture="texplane"
      texuniform="true" />
    <mesh name="LINK_BASE" file="xiaoliu/meshes/LINK_BASE.STL" />
    <mesh name="LINK_WAIST_M0" file="xiaoliu/meshes/LINK_WAIST_M0.STL" />
    <mesh name="LINK_NECK_M0" file="xiaoliu/meshes/LINK_NECK_M0.STL" />
    <mesh name="LINK_NECK_M1" file="xiaoliu/meshes/LINK_NECK_M1.STL" />
    <mesh name="LINK_BASE_L" file="xiaoliu/meshes/LINK_BASE_L.STL" />
    <mesh name="LINK_SHOULDER_L0" file="xiaoliu/meshes/LINK_SHOULDER_L0.STL" />
    <mesh name="LINK_SHOULDER_L1" file="xiaoliu/meshes/LINK_SHOULDER_L1.STL" />
    <mesh name="LINK_SHOULDER_L2" file="xiaoliu/meshes/LINK_SHOULDER_L2.STL" />
    <mesh name="LINK_ELBOW_L0" file="xiaoliu/meshes/LINK_ELBOW_L0.STL" />
    <mesh name="LINK_ELBOW_L1" file="xiaoliu/meshes/LINK_ELBOW_L1.STL" />
    <mesh name="LINK_WRIST_L0" file="xiaoliu/meshes/LINK_WRIST_L0.STL" />
    <mesh name="LINK_WRIST_L1" file="xiaoliu/meshes/LINK_WRIST_L1.STL" />
    <mesh name="LINK_BASE_R" file="xiaoliu/meshes/LINK_BASE_R.STL" />
    <mesh name="LINK_SHOULDER_R0" file="xiaoliu/meshes/LINK_SHOULDER_R0.STL" />
    <mesh name="LINK_SHOULDER_R1" file="xiaoliu/meshes/LINK_SHOULDER_R1.STL" />
    <mesh name="LINK_SHOULDER_R2" file="xiaoliu/meshes/LINK_SHOULDER_R2.STL" />
    <mesh name="LINK_ELBOW_R0" file="xiaoliu/meshes/LINK_ELBOW_R0.STL" />
    <mesh name="LINK_ELBOW_R1" file="xiaoliu/meshes/LINK_ELBOW_R1.STL" />
    <mesh name="LINK_WRIST_R0" file="xiaoliu/meshes/LINK_WRIST_R0.STL" />
    <mesh name="LINK_WRIST_R1" file="xiaoliu/meshes/LINK_WRIST_R1.STL" />
    <mesh name="LINK_HAND_BASE_L" file="xiaoliu/meshes/LINK_HAND_BASE_L.STL" />
    <mesh name="LINK_F0_L0" file="xiaoliu/meshes/LINK_F0_L0.STL" />
    <mesh name="LINK_F0_L1" file="xiaoliu/meshes/LINK_F0_L1.STL" />
    <mesh name="LINK_F0_L2" file="xiaoliu/meshes/LINK_F0_L2.STL" />
    <mesh name="LINK_F1_L0" file="xiaoliu/meshes/LINK_F1_L0.STL" />
    <mesh name="LINK_F1_L1" file="xiaoliu/meshes/LINK_F1_L1.STL" />
    <mesh name="LINK_F1_L2" file="xiaoliu/meshes/LINK_F1_L2.STL" />
    <mesh name="LINK_F2_L0" file="xiaoliu/meshes/LINK_F2_L0.STL" />
    <mesh name="LINK_F2_L1" file="xiaoliu/meshes/LINK_F2_L1.STL" />
    <mesh name="LINK_F2_L2" file="xiaoliu/meshes/LINK_F2_L2.STL" />
    <mesh name="LINK_HAND_BASE_R" file="xiaoliu/meshes/LINK_HAND_BASE_R.STL" />
    <material name="link_geom" rgba="0.5 0.9 0.2 1" />
    <!-- <texture type="skybox" builtin="gradient" rgb1=".3 .5 .7" rgb2="0 0 0" width="32"
    height="512"/> -->
    <!-- <texture name="grid" type="2d" builtin="checker" width="512" height="512" rgb1=".1 .2 .3"
    rgb2=".2 .3 .4"/> -->
    <!-- <material name="grid" texture="grid" texrepeat="1 1" texuniform="true" reflectance=".2"/> -->
  </asset>

  <worldbody>
    <!-- <light directional="true" diffuse="0.4 0.4 0.4" specular="0.1 0.1 0.1" pos="0 0 5.0" dir="0
    0 -1" castshadow="false" /> -->
    <!-- <light directional="true" diffuse="0.6 0.6 0.6" specular="0.2 0.2 0.2" pos="0 0 4" dir="0 0
    -1" /> -->
    <!-- <geom name="ground" type="plane" pos="0 0 0" size="100 100 0.001" quat="1 0 0 0"
    material="grid" contype="1" conaffinity="0"/> -->
    <!-- <camera name="fixed" pos="0 -3.0 0.7324946948063407" xyaxes="1 0 0 0 0 1" /> -->
    <!-- <camera name="track" mode="trackcom" pos="0 -3.0 0.7324946948063407" xyaxes="1 0 0 0 0 1" /> -->
    <body name="BASE_X">
      <inertial pos="0 0 0" mass="0.01" diaginertia="1e-06 1e-06 1e-06" />
      <joint name="J_BASE_X" pos="0 0 0" axis="1 0 0" type="slide" range="-10 10"
        actuatorfrcrange="-1000 1000" />
      <body name="BASE_Y">
        <inertial pos="0 0 0" mass="0.01" diaginertia="1e-06 1e-06 1e-06" />
        <joint name="J_BASE_Y" pos="0 0 0" axis="0 1 0" type="slide" range="-10 10"
          actuatorfrcrange="-1000 1000" />
        <body name="LINK_BASE">
          <inertial pos="-0.012524 4.3e-05 0.266752" quat="0.686869 -0.0756536 -0.079284 0.718471"
            mass="283.15" diaginertia="15.4585 10.9249 9.48999" />
          <joint name="J_BASE_YAW" pos="0 0 0" axis="0 0 1" range="-10 10"
            actuatorfrcrange="-1000 1000" />
          <geom type="mesh" rgba="0.7 0.7 0.7 1" mesh="LINK_BASE" group="1" class="link_geom" />
          <body name="LINK_WAIST_M0" pos="0.2994 0 0.9045">
            <inertial pos="0.0663561 -0.000630404 0.222636"
              quat="0.6954 -0.0793025 -0.0764952 0.710126" mass="40.1121"
              diaginertia="3.87674 3.81674 0.48263" />
            <joint name="J_WAIST_M0" pos="0 0 0" axis="0 0 1" type="slide" range="-0.3 0"
              actuatorfrcrange="-1000 1000" />
            <geom type="mesh" rgba="0.7 0.7 0.7 1" mesh="LINK_WAIST_M0" group="1" class="link_geom" />
            <body name="LINK_ARM_BASE_L" pos="0 0 0">
              <geom pos="0.172 0.096 0.539" quat="1 0 0 0" type="mesh" rgba="0.7 0.7 0.7 1"
                mesh="LINK_BASE_L" group="1" class="link_geom" />
            </body>
            <body name="LINK_ARM_BASE_R" pos="0 0 0">
              <geom pos="0.172 -0.096 0.539" quat="1 0 0 0" type="mesh" rgba="0.7 0.7 0.7 1"
                mesh="LINK_BASE_R" group="1" class="link_geom" />
            </body>
            <body name="LINK_NECK_M0" pos="0.162 0 0.611">
              <inertial pos="0.000314 0.000456 0.042045"
                quat="0.999002 0.0318979 0.0284492 -0.0129796" mass="0.953"
                diaginertia="0.000695173 0.000688189 0.000641637" />
              <joint name="J_NECK_M0" pos="0 0 0" axis="0 0 1" range="-2.9322 2.9322"
                actuatorfrcrange="-19 19" />
              <geom type="mesh" rgba="0.7 0.7 0.7 1" mesh="LINK_NECK_M0" group="1" class="link_geom" />
              <body name="LINK_NECK_M1" pos="0 0 0.044" quat="0.707105 -0.707108 0 0">
                <inertial pos="-0.00311 -0.118218 -0.000205"
                  quat="0.986477 -0.0132952 -0.00970629 -0.163069" mass="0.648"
                  diaginertia="0.0015796 0.001257 0.000863396" />
                <joint name="J_NECK_M1" pos="0 0 0" axis="0 0 1" range="-0.0524 1.2741"
                  actuatorfrcrange="-19 19" />
                <geom type="mesh" rgba="0.7 0.7 0.7 1" mesh="LINK_NECK_M1" group="1"
                  class="link_geom" />
              </body>
            </body>
            <body name="LINK_SHOULDER_L0" pos="0.172 0.16495 0.539"
              quat="0.499998 -0.5 0.5 0.500002">
              <inertial pos="-0.002053 0.000827 -0.012825"
                quat="0.729889 -0.0549253 -0.0440975 0.679927" mass="0.2392"
                diaginertia="0.000145082 0.000132781 8.91368e-05" />
              <joint name="J_SHOULDER_L0" pos="0 0 0" axis="0 0 1" range="-2.8798 1.0472"
                actuatorfrcrange="-117 117" />
              <geom type="mesh" rgba="0.7 0.7 0.7 1" mesh="LINK_SHOULDER_L0" group="1"
                class="link_geom" />
              <body name="LINK_SHOULDER_L1" quat="0.707105 0.707108 0 0">
                <inertial pos="0.044196 0.021385 -0.01858"
                  quat="0.314021 0.744573 0.262179 0.527507" mass="1.7672"
                  diaginertia="0.00574424 0.00396264 0.00219111" />
                <joint name="J_SHOULDER_L1" pos="0 0 0" axis="0 0 1" range="-0.5236 2.4434"
                  actuatorfrcrange="-117 117" />
                <geom type="mesh" rgba="0.7 0.7 0.7 1" mesh="LINK_SHOULDER_L1" group="1"
                  class="link_geom" />
                <body name="LINK_SHOULDER_L2" pos="0.1035 0.04 0" quat="0.707105 0 0.707108 0">
                  <inertial pos="2e-06 0.007424 0.1136" quat="0.552089 0.0238789 -0.010735 0.833374"
                    mass="1.6352" diaginertia="0.00731771 0.00719387 0.00126342" />
                  <joint name="J_SHOULDER_L2" pos="0 0 0" axis="0 0 1" range="-2.618 2.618"
                    actuatorfrcrange="-65 65" />
                  <geom type="mesh" rgba="0.7 0.7 0.7 1" mesh="LINK_SHOULDER_L2" group="1"
                    class="link_geom" />
                  <body name="LINK_ELBOW_L0" pos="0 0 0.2165" quat="0.707105 0 -0.707108 0">
                    <inertial pos="0.003887 -0.000124 -0.000164" quat="0.707107 0 0 0.707107"
                      mass="0.15153" diaginertia="0.00014 0.000127 2.8e-05" />
                    <joint name="J_ELBOW_L0" pos="0 0 0" axis="0 0 1" range="-2.2689 0"
                      actuatorfrcrange="-66 66" />
                    <geom type="mesh" rgba="0.7 0.7 0.7 1" mesh="LINK_ELBOW_L0" group="1"
                      class="link_geom" />
                    <body name="LINK_ELBOW_L1" quat="0.707105 0 0.707108 0">
                      <inertial pos="-2.9e-05 -0.000267 0.14122"
                        quat="0.706751 -0.0186977 0.018537 0.706972" mass="1.1669"
                        diaginertia="0.00497623 0.004805 0.00056277" />
                      <joint name="J_ELBOW_L1" pos="0 0 0" axis="0 0 1" range="-2.3562 2.3562"
                        actuatorfrcrange="-66 66" />
                      <geom type="mesh" rgba="0.7 0.7 0.7 1" mesh="LINK_ELBOW_L1" group="1"
                        class="link_geom" />
                      <body name="LINK_WRIST_L0" pos="0 0 0.28" quat="0.499998 -0.5 -0.5 -0.500002">
                        <inertial pos="-0.000267 -0.000273 -3.5e-05" mass="0.075056"
                          diaginertia="3.6e-05 3.4e-05 1.1e-05" />
                        <joint name="J_WRIST_L0" pos="0 0 0" axis="0 0 1" range="-0.8727 0.8727"
                          actuatorfrcrange="-41 41" />
                        <geom type="mesh" rgba="0.7 0.7 0.7 1" mesh="LINK_WRIST_L0" group="1"
                          class="link_geom" />
                        <body name="LINK_WRIST_L1" quat="0.707105 0.707108 0 0">
                          <inertial pos="0.0951701 -0.000142407 -0.00402647"
                            quat="0.477652 0.553024 0.466941 0.497975" mass="0.644253"
                            diaginertia="0.00125342 0.00104168 0.000480612" />
                          <joint name="J_WRIST_L1" pos="0 0 0" axis="0 0 1" range="-1.5708 1.3963"
                            actuatorfrcrange="-41 41" />
                          <geom type="mesh" rgba="0.7 0.7 0.7 1" mesh="LINK_WRIST_L1" group="1"
                            class="link_geom" />
                          <geom pos="0.0555 0 0" quat="0.707105 0.707108 0 0" type="mesh"
                            rgba="0.7 0.7 0.7 1" mesh="LINK_HAND_BASE_L" group="1" class="link_geom" />
                          <body name="LINK_F0_L0" pos="0.076999 -0.0208651 0.0224999"
                            quat="-2.59734e-06 0.707105 0 0.707108">
                            <inertial pos="-3.617e-05 0 -0.00084515" mass="0.026087"
                              diaginertia="1.92e-06 1.52e-06 1.22e-06" />
                            <joint name="J_F0_L0" pos="0 0 0" axis="0 0 1" range="0 1.9199"
                              actuatorfrcrange="-3 3" />
                            <geom type="mesh" rgba="0.7 0.7 0.7 1" mesh="LINK_F0_L0" group="1"
                              class="link_geom" />
                            <body name="LINK_F0_L1" quat="0.707105 0.707108 0 0">
                              <inertial pos="0.0375062 -8.894e-05 0.0001648"
                                quat="0.511508 0.483488 0.515615 0.48861" mass="0.0688816"
                                diaginertia="2.05529e-05 2.00084e-05 6.49879e-06" />
                              <joint name="J_F0_L1" pos="0 0 0" axis="0 0 1" range="-0.1745 0.7854"
                                actuatorfrcrange="-3 3" />
                              <geom type="mesh" rgba="0.7 0.7 0.7 1" mesh="LINK_F0_L1" group="1"
                                class="link_geom" />
                              <body name="LINK_F0_L2" pos="0.05425 0 0">
                                <inertial pos="0.0208975 -0.00213483 -0.00106078"
                                  quat="0.479898 0.503774 0.561192 0.448301" mass="0.0310237"
                                  diaginertia="7.08669e-06 6.49441e-06 2.3189e-06" />
                                <joint name="J_F0_L2" pos="0 0 0" axis="0 0 1"
                                  range="-0.4363 1.5708" actuatorfrcrange="-1.5 1.5" />
                                <geom type="mesh" rgba="0.7 0.7 0.7 1" mesh="LINK_F0_L2" group="1"
                                  class="link_geom" />
                              </body>
                            </body>
                          </body>
                          <body name="LINK_F1_L0" pos="0.15782 -0.00574008 0.0225"
                            quat="-3.67321e-06 1 0 0">
                            <inertial pos="3.617e-05 0 0.00084515" mass="0.026087"
                              diaginertia="1.92e-06 1.52e-06 1.22e-06" />
                            <joint name="J_F1_L0" pos="0 0 0" axis="0 0 1" range="-0.4363 1.8326"
                              actuatorfrcrange="-3 3" />
                            <geom type="mesh" rgba="0.7 0.7 0.7 1" mesh="LINK_F1_L0" group="1"
                              class="link_geom" />
                            <body name="LINK_F1_L1" quat="0.707105 -0.707108 0 0">
                              <inertial pos="0.0324375 -0.00016602 -0.0001648"
                                quat="0.492035 0.508606 0.488885 0.51011" mass="0.0702732"
                                diaginertia="1.85812e-05 1.77891e-05 6.95973e-06" />
                              <joint name="J_F1_L1" pos="0 0 0" axis="0 0 1" range="-0.4363 0.4363"
                                actuatorfrcrange="-3 3" />
                              <geom type="mesh" rgba="0.7 0.7 0.7 1" mesh="LINK_F1_L1" group="1"
                                class="link_geom" />
                              <body name="LINK_F1_L2" pos="0.04825 0 0" quat="0.707105 0.707108 0 0">
                                <inertial pos="0.0208065 -0.00102362 -0.00132199"
                                  quat="0.466616 0.545959 0.523663 0.458231" mass="0.0257518"
                                  diaginertia="6.36399e-06 5.8103e-06 1.96571e-06" />
                                <joint name="J_F1_L2" pos="0 0 0" axis="0 0 1"
                                  range="-0.4363 1.5708" actuatorfrcrange="-1.5 1.5" />
                                <geom type="mesh" rgba="0.7 0.7 0.7 1" mesh="LINK_F1_L2" group="1"
                                  class="link_geom" />
                              </body>
                            </body>
                          </body>
                          <body name="LINK_F2_L0" pos="0.15782 -0.00573992 -0.0225"
                            quat="-3.67321e-06 1 0 0">
                            <inertial pos="3.617e-05 0 0.00084515" mass="0.026087"
                              diaginertia="1.92e-06 1.52e-06 1.22e-06" />
                            <joint name="J_F2_L0" pos="0 0 0" axis="0 0 1" range="-0.4363 1.8326"
                              actuatorfrcrange="-3 3" />
                            <geom type="mesh" rgba="0.7 0.7 0.7 1" mesh="LINK_F2_L0" group="1"
                              class="link_geom" />
                            <body name="LINK_F2_L1" quat="0.707105 -0.707108 0 0">
                              <inertial pos="0.0324375 -0.00016602 -0.0001648"
                                quat="0.492035 0.508606 0.488885 0.51011" mass="0.0702732"
                                diaginertia="1.85812e-05 1.77891e-05 6.95973e-06" />
                              <joint name="J_F2_L1" pos="0 0 0" axis="0 0 1" range="-0.4363 0.4363"
                                actuatorfrcrange="-3 3" />
                              <geom type="mesh" rgba="0.7 0.7 0.7 1" mesh="LINK_F2_L1" group="1"
                                class="link_geom" />
                              <body name="LINK_F2_L2" pos="0.04825 0 0" quat="0.707105 0.707108 0 0">
                                <inertial pos="0.0208065 -0.00102362 -0.00132199"
                                  quat="0.466616 0.545959 0.523663 0.458231" mass="0.0257518"
                                  diaginertia="6.36399e-06 5.8103e-06 1.96571e-06" />
                                <joint name="J_F2_L2" pos="0 0 0" axis="0 0 1"
                                  range="-0.4363 1.5708" actuatorfrcrange="-1.5 1.5" />
                                <geom type="mesh" rgba="0.7 0.7 0.7 1" mesh="LINK_F2_L2" group="1"
                                  class="link_geom" />
                              </body>
                            </body>
                          </body>
                        </body>
                      </body>
                    </body>
                  </body>
                </body>
              </body>
            </body>
            <body name="LINK_SHOULDER_R0" pos="0.172 -0.16495 0.539"
              quat="0.499998 -0.5 0.5 0.500002">
              <inertial pos="-0.002053 0.000827 0.012825"
                quat="0.729889 -0.0549253 -0.0440975 0.679927" mass="0.2392"
                diaginertia="0.000145082 0.000132781 8.91368e-05" />
              <joint name="J_SHOULDER_R0" pos="0 0 0" axis="0 0 1" range="-2.8798 1.0472"
                actuatorfrcrange="-117 117" />
              <geom type="mesh" rgba="0.7 0.7 0.7 1" mesh="LINK_SHOULDER_R0" group="1"
                class="link_geom" />
              <body name="LINK_SHOULDER_R1" quat="0.707105 0.707108 0 0">
                <inertial pos="0.044196 -0.021385 -0.01858"
                  quat="0.314021 0.744573 0.262179 0.527507" mass="1.7672"
                  diaginertia="0.00574424 0.00396264 0.00219111" />
                <joint name="J_SHOULDER_R1" pos="0 0 0" axis="0 0 1" range="-2.4434 0.5236"
                  actuatorfrcrange="-117 117" />
                <geom type="mesh" rgba="0.7 0.7 0.7 1" mesh="LINK_SHOULDER_R1" group="1"
                  class="link_geom" />
                <body name="LINK_SHOULDER_R2" pos="0.1035 -0.04 0" quat="0.707105 0 0.707108 0">
                  <inertial pos="2e-06 -0.007424 0.1136"
                    quat="0.552089 0.0238789 -0.010735 0.833374" mass="1.6352"
                    diaginertia="0.00731771 0.00719387 0.00126342" />
                  <joint name="J_SHOULDER_R2" pos="0 0 0" axis="0 0 1" range="-2.618 2.618"
                    actuatorfrcrange="-65 65" />
                  <geom type="mesh" rgba="0.7 0.7 0.7 1" mesh="LINK_SHOULDER_R2" group="1"
                    class="link_geom" />
                  <body name="LINK_ELBOW_R0" pos="0 0 0.2165" quat="0.707105 0 -0.707108 0">
                    <inertial pos="0.003887 0.000124 -0.000164" quat="0.707107 0 0 0.707107"
                      mass="0.15153" diaginertia="0.00014 0.000127 2.8e-05" />
                    <joint name="J_ELBOW_R0" pos="0 0 0" axis="0 0 1" range="0 2.2689"
                      actuatorfrcrange="-66 66" />
                    <geom type="mesh" rgba="0.7 0.7 0.7 1" mesh="LINK_ELBOW_R0" group="1"
                      class="link_geom" />
                    <body name="LINK_ELBOW_R1" quat="0.707105 0 0.707108 0">
                      <inertial pos="-2.9e-05 0.000267 0.14122"
                        quat="0.706751 -0.0186977 0.018537 0.706972" mass="1.1669"
                        diaginertia="0.00497623 0.004805 0.00056277" />
                      <joint name="J_ELBOW_R1" pos="0 0 0" axis="0 0 1" range="-2.3562 2.3562"
                        actuatorfrcrange="-66 66" />
                      <geom type="mesh" rgba="0.7 0.7 0.7 1" mesh="LINK_ELBOW_R1" group="1"
                        class="link_geom" />
                      <body name="LINK_WRIST_R0" pos="0 0 0.28" quat="0.499998 -0.5 -0.5 -0.500002">
                        <inertial pos="-0.000267 -0.000273 3.5e-05" mass="0.075056"
                          diaginertia="3.6e-05 3.4e-05 1.1e-05" />
                        <joint name="J_WRIST_R0" pos="0 0 0" axis="0 0 1" range="-0.8727 0.8727"
                          actuatorfrcrange="-41 41" />
                        <geom type="mesh" rgba="0.7 0.7 0.7 1" mesh="LINK_WRIST_R0" group="1"
                          class="link_geom" />
                        <body name="LINK_WRIST_R1" quat="0.707105 0.707108 0 0">
                          <inertial pos="0.0951701 0.000142407 -0.00402647"
                            quat="0.514889 0.451447 0.52827 0.502012" mass="0.644253"
                            diaginertia="0.00125284 0.00104164 0.000481235" />
                          <joint name="J_WRIST_R1" pos="0 0 0" axis="0 0 1" range="-1.3963 1.5708"
                            actuatorfrcrange="-41 41" />
                          <geom type="mesh" rgba="0.7 0.7 0.7 1" mesh="LINK_WRIST_R1" group="1"
                            class="link_geom" />
                          <geom pos="0.0555 0 0" quat="0.707105 -0.707108 0 0" type="mesh"
                            rgba="0.7 0.7 0.7 1" mesh="LINK_HAND_BASE_R" group="1" class="link_geom" />
                          <body name="LINK_F0_R0" pos="0.076999 0.0208651 0.0224999"
                            quat="0.707105 0 -0.707108 2.59735e-06">
                            <inertial pos="-3.617e-05 0 0.00084515" mass="0.026087"
                              diaginertia="1.92e-06 1.52e-06 1.22e-06" />
                            <joint name="J_F0_R0" pos="0 0 0" axis="0 0 1" range="0 1.9199"
                              actuatorfrcrange="-3 3" />
                            <geom type="mesh" rgba="0.7 0.7 0.7 1" mesh="LINK_F0_L0" group="1"
                              class="link_geom" />
                            <body name="LINK_F0_R1" quat="0.707105 -0.707108 0 0">
                              <inertial pos="0.0375062 -8.894e-05 -0.0001648"
                                quat="0.483488 0.511508 0.48861 0.515615" mass="0.0688816"
                                diaginertia="2.05529e-05 2.00084e-05 6.49879e-06" />
                              <joint name="J_F0_R1" pos="0 0 0" axis="0 0 1" range="-0.1745 0.7854"
                                actuatorfrcrange="-3 3" />
                              <geom type="mesh" rgba="0.7 0.7 0.7 1" mesh="LINK_F0_L1" group="1"
                                class="link_geom" />
                              <body name="LINK_F0_R2" pos="0.05425 0 0">
                                <inertial pos="0.0208975 -0.00213483 0.00106078"
                                  quat="0.447875 0.539993 0.526612 0.480099" mass="0.0310237"
                                  diaginertia="7.08344e-06 6.49812e-06 2.31845e-06" />
                                <joint name="J_F0_R2" pos="0 0 0" axis="0 0 1"
                                  range="-0.4363 1.5708" actuatorfrcrange="-1.5 1.5" />
                                <geom type="mesh" rgba="0.7 0.7 0.7 1" mesh="LINK_F0_L2" group="1"
                                  class="link_geom" />
                              </body>
                            </body>
                          </body>
                          <body name="LINK_F1_R0" pos="0.15782 0.00574008 0.0225">
                            <inertial pos="3.617e-05 0 -0.00084515" mass="0.026087"
                              diaginertia="1.92e-06 1.52e-06 1.22e-06" />
                            <joint name="J_F1_R0" pos="0 0 0" axis="0 0 1" range="-0.4363 1.8326"
                              actuatorfrcrange="-3 3" />
                            <geom type="mesh" rgba="0.7 0.7 0.7 1" mesh="LINK_F1_L0" group="1"
                              class="link_geom" />
                            <body name="LINK_F1_R1" quat="0.707105 0.707108 0 0">
                              <inertial pos="0.0324375 -0.00016602 0.0001648"
                                quat="0.508606 0.492035 0.51011 0.488885" mass="0.0702732"
                                diaginertia="1.85812e-05 1.77891e-05 6.95973e-06" />
                              <joint name="J_F1_R1" pos="0 0 0" axis="0 0 1" range="-0.4363 0.4363"
                                actuatorfrcrange="-3 3" />
                              <geom type="mesh" rgba="0.7 0.7 0.7 1" mesh="LINK_F1_L1" group="1"
                                class="link_geom" />
                              <body name="LINK_F1_R2" pos="0.04825 0 0"
                                quat="0.707105 -0.707108 0 0">
                                <inertial pos="0.0208065 -0.00102362 0.00132199"
                                  quat="0.545959 0.466616 0.458231 0.523663" mass="0.0257518"
                                  diaginertia="6.36399e-06 5.8103e-06 1.96571e-06" />
                                <joint name="J_F1_R2" pos="0 0 0" axis="0 0 1"
                                  range="-0.4363 1.5708" actuatorfrcrange="-1.5 1.5" />
                                <geom type="mesh" rgba="0.7 0.7 0.7 1" mesh="LINK_F1_L2" group="1"
                                  class="link_geom" />
                              </body>
                            </body>
                          </body>
                          <body name="LINK_F2_R0" pos="0.15782 0.00573992 -0.0225">
                            <inertial pos="3.617e-05 0 -0.00084515" mass="0.026087"
                              diaginertia="1.92e-06 1.52e-06 1.22e-06" />
                            <joint name="J_F2_R0" pos="0 0 0" axis="0 0 1" range="-0.4363 1.8326"
                              actuatorfrcrange="-3 3" />
                            <geom type="mesh" rgba="0.7 0.7 0.7 1" mesh="LINK_F2_L0" group="1"
                              class="link_geom" />
                            <body name="LINK_F2_R1" quat="0.707105 0.707108 0 0">
                              <inertial pos="0.0324375 -0.00016602 0.0001648"
                                quat="0.508606 0.492035 0.51011 0.488885" mass="0.0702732"
                                diaginertia="1.85812e-05 1.77891e-05 6.95973e-06" />
                              <joint name="J_F2_R1" pos="0 0 0" axis="0 0 1" range="-0.4363 0.4363"
                                actuatorfrcrange="-3 3" />
                              <geom type="mesh" rgba="0.7 0.7 0.7 1" mesh="LINK_F2_L1" group="1"
                                class="link_geom" />
                              <body name="LINK_F2_R2" pos="0.04825 0 0"
                                quat="0.707105 -0.707108 0 0">
                                <inertial pos="0.0208065 -0.00102362 0.00132199"
                                  quat="0.545959 0.466616 0.458231 0.523663" mass="0.0257518"
                                  diaginertia="6.36399e-06 5.8103e-06 1.96571e-06" />
                                <joint name="J_F2_R2" pos="0 0 0" axis="0 0 1"
                                  range="-0.4363 1.5708" actuatorfrcrange="-1.5 1.5" />
                                <geom type="mesh" rgba="0.7 0.7 0.7 1" mesh="LINK_F2_L2" group="1"
                                  class="link_geom" />
                              </body>
                            </body>
                          </body>
                        </body>
                      </body>
                    </body>
                  </body>
                </body>
              </body>
            </body>
          </body>
        </body>
      </body>
    </body>
  </worldbody>

  <actuator>
    <position name="J_BASE_X" joint="J_BASE_X" forcerange="-1000 1000" ctrlrange="-10 10" kv="1000" />
    <position name="J_BASE_Y" joint="J_BASE_Y" forcerange="-1000 1000" ctrlrange="-10 10" kv="1000" />
    <position name="J_BASE_YAW" joint="J_BASE_YAW" forcerange="-1000 1000" ctrlrange="-10 10"
      kv="500" />
    <position name="J_WAIST_M0" joint="J_WAIST_M0" forcerange="-1000 1000" ctrlrange="-0.3 0"
      kp="100000" kv="10000" />
    <position name="J_NECK_M0" joint="J_NECK_M0" forcerange="-19 19" ctrlrange="-2.9322 2.9322"
      kp="10" kv="1" />
    <position name="J_NECK_M1" joint="J_NECK_M1" forcerange="-19 19" ctrlrange="-0.0524 1.2741"
      kp="10" kv="1" />

    <position name="J_SHOULDER_L0" joint="J_SHOULDER_L0" forcerange="-117 117"
      ctrlrange="-2.8798 1.0472" kp="10000" kv="500" />
    <position name="J_SHOULDER_L1" joint="J_SHOULDER_L1" forcerange="-117 117"
      ctrlrange="-0.5236 2.4434" kp="10000" kv="500" />
    <position name="J_SHOULDER_L2" joint="J_SHOULDER_L2" forcerange="-65 65"
      ctrlrange="-2.6180 2.6180" kp="1000" kv="0.01" />
    <position name="J_ELBOW_L0" joint="J_ELBOW_L0" forcerange="-66 66" ctrlrange="-2.2689 0"
      kp="1000" kv="10" />
    <position name="J_ELBOW_L1" joint="J_ELBOW_L1" forcerange="-66 66" ctrlrange="-2.3562 2.3562"
      kp="100" kv="1" />
    <position name="J_WRIST_L0" joint="J_WRIST_L0" forcerange="-41 41" ctrlrange="-0.8727 0.8727"
      kp="100" kv="1" />
    <position name="J_WRIST_L1" joint="J_WRIST_L1" forcerange="-41 41" ctrlrange="-1.5708 1.3963"
      kp="100" kv="1" />
    <position name="J_F0_L0" joint="J_F0_L0" forcerange="-3 3" ctrlrange="0 1.9199"
      class="hand_joint" />
    <position name="J_F0_L1" joint="J_F0_L1" forcerange="-3 3" ctrlrange="-0.1745 0.7854"
      class="hand_joint" />
    <position name="J_F0_L2" joint="J_F0_L2" forcerange="-1.5 1.5" ctrlrange="-0.4363 1.5708"
      class="hand_joint" />
    <position name="J_F1_L0" joint="J_F1_L0" forcerange="-3 3" ctrlrange="-0.4363 1.8326"
      class="hand_joint" />
    <position name="J_F1_L1" joint="J_F1_L1" forcerange="-3 3" ctrlrange="-0.4363 0.4363"
      class="hand_joint" />
    <position name="J_F1_L2" joint="J_F1_L2" forcerange="-1.5 1.5" ctrlrange="-0.4363 1.5708"
      class="hand_joint" />
    <position name="J_F2_L0" joint="J_F2_L0" forcerange="-3 3" ctrlrange="-0.4363 1.8326"
      class="hand_joint" />
    <position name="J_F2_L1" joint="J_F2_L1" forcerange="-3 3" ctrlrange="-0.4363 0.4363"
      class="hand_joint" />
    <position name="J_F2_L2" joint="J_F2_L2" forcerange="-1.5 1.5" ctrlrange="-0.4363 1.5708"
      class="hand_joint" />

    <position name="J_SHOULDER_R0" joint="J_SHOULDER_R0" forcerange="-117 117"
      ctrlrange="-2.8798 1.0472" kp="10000" kv="500" />
    <position name="J_SHOULDER_R1" joint="J_SHOULDER_R1" forcerange="-117 117"
      ctrlrange="-2.4434 0.5236" kp="10000" kv="500" />
    <position name="J_SHOULDER_R2" joint="J_SHOULDER_R2" forcerange="-65 65"
      ctrlrange="-2.6180 2.6180" kp="1000" kv="0.01" />
    <position name="J_ELBOW_R0" joint="J_ELBOW_R0" forcerange="-66 66" ctrlrange="0 2.2689"
      kp="1000" kv="10" />
    <position name="J_ELBOW_R1" joint="J_ELBOW_R1" forcerange="-66 66" ctrlrange="-2.3562 2.3562"
      kp="100" kv="1" />
    <position name="J_WRIST_R0" joint="J_WRIST_R0" forcerange="-41 41" ctrlrange="-0.8727 0.8727"
      kp="100" kv="1" />
    <position name="J_WRIST_R1" joint="J_WRIST_R1" forcerange="-41 41" ctrlrange="-1.3963 1.5708"
      kp="100" kv="1" />
    <position name="J_F0_R0" joint="J_F0_R0" forcerange="-3 3" ctrlrange="0 1.9199"
      class="hand_joint" />
    <position name="J_F0_R1" joint="J_F0_R1" forcerange="-3 3" ctrlrange="-0.1745 0.7854"
      class="hand_joint" />
    <position name="J_F0_R2" joint="J_F0_R2" forcerange="-1.5 1.5" ctrlrange="-0.4363 1.5708"
      class="hand_joint" />
    <position name="J_F1_R0" joint="J_F1_R0" forcerange="-3 3" ctrlrange="-0.4363 1.8326"
      class="hand_joint" />
    <position name="J_F1_R1" joint="J_F1_R1" forcerange="-3 3" ctrlrange="-0.4363 0.4363"
      class="hand_joint" />
    <position name="J_F1_R2" joint="J_F1_R2" forcerange="-1.5 1.5" ctrlrange="-0.4363 1.5708"
      class="hand_joint" />
    <position name="J_F2_R0" joint="J_F2_R0" forcerange="-3 3" ctrlrange="-0.4363 1.8326"
      class="hand_joint" />
    <position name="J_F2_R1" joint="J_F2_R1" forcerange="-3 3" ctrlrange="-0.4363 0.4363"
      class="hand_joint" />
    <position name="J_F2_R2" joint="J_F2_R2" forcerange="-1.5 1.5" ctrlrange="-0.4363 1.5708"
      class="hand_joint" />
  </actuator>

  <sensor>
    <actuatorpos name="J_BASE_X_p" actuator="J_BASE_X" />
    <actuatorvel name="J_BASE_X_v" actuator="J_BASE_X" />
    <actuatorfrc name="J_BASE_X_f" actuator="J_BASE_X" noise="0.001" />
    <actuatorpos name="J_BASE_Y_p" actuator="J_BASE_Y" />
    <actuatorvel name="J_BASE_Y_v" actuator="J_BASE_Y" />
    <actuatorfrc name="J_BASE_Y_f" actuator="J_BASE_Y" noise="0.001" />
    <actuatorpos name="J_BASE_YAW_p" actuator="J_BASE_YAW" />
    <actuatorvel name="J_BASE_YAW_v" actuator="J_BASE_YAW" />
    <actuatorfrc name="J_BASE_YAW_f" actuator="J_BASE_YAW" noise="0.001" />
    <actuatorpos name="J_WAIST_M0_p" actuator="J_WAIST_M0" />
    <actuatorvel name="J_WAIST_M0_v" actuator="J_WAIST_M0" />
    <actuatorfrc name="J_WAIST_M0_f" actuator="J_WAIST_M0" noise="0.001" />
    <actuatorpos name="J_NECK_M0_p" actuator="J_NECK_M0" />
    <actuatorvel name="J_NECK_M0_v" actuator="J_NECK_M0" />
    <actuatorfrc name="J_NECK_M0_f" actuator="J_NECK_M0" noise="0.001" />
    <actuatorpos name="J_NECK_M1_p" actuator="J_NECK_M1" />
    <actuatorvel name="J_NECK_M1_v" actuator="J_NECK_M1" />
    <actuatorfrc name="J_NECK_M1_f" actuator="J_NECK_M1" noise="0.001" />
    <actuatorpos name="J_SHOULDER_L0_p" actuator="J_SHOULDER_L0" />
    <actuatorvel name="J_SHOULDER_L0_v" actuator="J_SHOULDER_L0" />
    <actuatorfrc name="J_SHOULDER_L0_f" actuator="J_SHOULDER_L0" noise="0.001" />
    <actuatorpos name="J_SHOULDER_L1_p" actuator="J_SHOULDER_L1" />
    <actuatorvel name="J_SHOULDER_L1_v" actuator="J_SHOULDER_L1" />
    <actuatorfrc name="J_SHOULDER_L1_f" actuator="J_SHOULDER_L1" noise="0.001" />
    <actuatorpos name="J_SHOULDER_L2_p" actuator="J_SHOULDER_L2" />
    <actuatorvel name="J_SHOULDER_L2_v" actuator="J_SHOULDER_L2" />
    <actuatorfrc name="J_SHOULDER_L2_f" actuator="J_SHOULDER_L2" noise="0.001" />
    <actuatorpos name="J_ELBOW_L0_p" actuator="J_ELBOW_L0" />
    <actuatorvel name="J_ELBOW_L0_v" actuator="J_ELBOW_L0" />
    <actuatorfrc name="J_ELBOW_L0_f" actuator="J_ELBOW_L0" noise="0.001" />
    <actuatorpos name="J_ELBOW_L1_p" actuator="J_ELBOW_L1" />
    <actuatorvel name="J_ELBOW_L1_v" actuator="J_ELBOW_L1" />
    <actuatorfrc name="J_ELBOW_L1_f" actuator="J_ELBOW_L1" noise="0.001" />
    <actuatorpos name="J_WRIST_L0_p" actuator="J_WRIST_L0" />
    <actuatorvel name="J_WRIST_L0_v" actuator="J_WRIST_L0" />
    <actuatorfrc name="J_WRIST_L0_f" actuator="J_WRIST_L0" noise="0.001" />
    <actuatorpos name="J_WRIST_L1_p" actuator="J_WRIST_L1" />
    <actuatorvel name="J_WRIST_L1_v" actuator="J_WRIST_L1" />
    <actuatorfrc name="J_WRIST_L1_f" actuator="J_WRIST_L1" noise="0.001" />
    <actuatorpos name="J_F0_L0_p" actuator="J_F0_L0" />
    <actuatorvel name="J_F0_L0_v" actuator="J_F0_L0" />
    <actuatorfrc name="J_F0_L0_f" actuator="J_F0_L0" noise="0.001" />
    <actuatorpos name="J_F0_L1_p" actuator="J_F0_L1" />
    <actuatorvel name="J_F0_L1_v" actuator="J_F0_L1" />
    <actuatorfrc name="J_F0_L1_f" actuator="J_F0_L1" noise="0.001" />
    <actuatorpos name="J_F0_L2_p" actuator="J_F0_L2" />
    <actuatorvel name="J_F0_L2_v" actuator="J_F0_L2" />
    <actuatorfrc name="J_F0_L2_f" actuator="J_F0_L2" noise="0.001" />
    <actuatorpos name="J_F1_L0_p" actuator="J_F1_L0" />
    <actuatorvel name="J_F1_L0_v" actuator="J_F1_L0" />
    <actuatorfrc name="J_F1_L0_f" actuator="J_F1_L0" noise="0.001" />
    <actuatorpos name="J_F1_L1_p" actuator="J_F1_L1" />
    <actuatorvel name="J_F1_L1_v" actuator="J_F1_L1" />
    <actuatorfrc name="J_F1_L1_f" actuator="J_F1_L1" noise="0.001" />
    <actuatorpos name="J_F1_L2_p" actuator="J_F1_L2" />
    <actuatorvel name="J_F1_L2_v" actuator="J_F1_L2" />
    <actuatorfrc name="J_F1_L2_f" actuator="J_F1_L2" noise="0.001" />
    <actuatorpos name="J_F2_L0_p" actuator="J_F2_L0" />
    <actuatorvel name="J_F2_L0_v" actuator="J_F2_L0" />
    <actuatorfrc name="J_F2_L0_f" actuator="J_F2_L0" noise="0.001" />
    <actuatorpos name="J_F2_L1_p" actuator="J_F2_L1" />
    <actuatorvel name="J_F2_L1_v" actuator="J_F2_L1" />
    <actuatorfrc name="J_F2_L1_f" actuator="J_F2_L1" noise="0.001" />
    <actuatorpos name="J_F2_L2_p" actuator="J_F2_L2" />
    <actuatorvel name="J_F2_L2_v" actuator="J_F2_L2" />
    <actuatorfrc name="J_F2_L2_f" actuator="J_F2_L2" noise="0.001" />
    <actuatorpos name="J_SHOULDER_R0_p" actuator="J_SHOULDER_R0" />
    <actuatorvel name="J_SHOULDER_R0_v" actuator="J_SHOULDER_R0" />
    <actuatorfrc name="J_SHOULDER_R0_f" actuator="J_SHOULDER_R0" noise="0.001" />
    <actuatorpos name="J_SHOULDER_R1_p" actuator="J_SHOULDER_R1" />
    <actuatorvel name="J_SHOULDER_R1_v" actuator="J_SHOULDER_R1" />
    <actuatorfrc name="J_SHOULDER_R1_f" actuator="J_SHOULDER_R1" noise="0.001" />
    <actuatorpos name="J_SHOULDER_R2_p" actuator="J_SHOULDER_R2" />
    <actuatorvel name="J_SHOULDER_R2_v" actuator="J_SHOULDER_R2" />
    <actuatorfrc name="J_SHOULDER_R2_f" actuator="J_SHOULDER_R2" noise="0.001" />
    <actuatorpos name="J_ELBOW_R0_p" actuator="J_ELBOW_R0" />
    <actuatorvel name="J_ELBOW_R0_v" actuator="J_ELBOW_R0" />
    <actuatorfrc name="J_ELBOW_R0_f" actuator="J_ELBOW_R0" noise="0.001" />
    <actuatorpos name="J_ELBOW_R1_p" actuator="J_ELBOW_R1" />
    <actuatorvel name="J_ELBOW_R1_v" actuator="J_ELBOW_R1" />
    <actuatorfrc name="J_ELBOW_R1_f" actuator="J_ELBOW_R1" noise="0.001" />
    <actuatorpos name="J_WRIST_R0_p" actuator="J_WRIST_R0" />
    <actuatorvel name="J_WRIST_R0_v" actuator="J_WRIST_R0" />
    <actuatorfrc name="J_WRIST_R0_f" actuator="J_WRIST_R0" noise="0.001" />
    <actuatorpos name="J_WRIST_R1_p" actuator="J_WRIST_R1" />
    <actuatorvel name="J_WRIST_R1_v" actuator="J_WRIST_R1" />
    <actuatorfrc name="J_WRIST_R1_f" actuator="J_WRIST_R1" noise="0.001" />
    <actuatorpos name="J_F0_R0_p" actuator="J_F0_R0" />
    <actuatorvel name="J_F0_R0_v" actuator="J_F0_R0" />
    <actuatorfrc name="J_F0_R0_f" actuator="J_F0_R0" noise="0.001" />
    <actuatorpos name="J_F0_R1_p" actuator="J_F0_R1" />
    <actuatorvel name="J_F0_R1_v" actuator="J_F0_R1" />
    <actuatorfrc name="J_F0_R1_f" actuator="J_F0_R1" noise="0.001" />
    <actuatorpos name="J_F0_R2_p" actuator="J_F0_R2" />
    <actuatorvel name="J_F0_R2_v" actuator="J_F0_R2" />
    <actuatorfrc name="J_F0_R2_f" actuator="J_F0_R2" noise="0.001" />
    <actuatorpos name="J_F1_R0_p" actuator="J_F1_R0" />
    <actuatorvel name="J_F1_R0_v" actuator="J_F1_R0" />
    <actuatorfrc name="J_F1_R0_f" actuator="J_F1_R0" noise="0.001" />
    <actuatorpos name="J_F1_R1_p" actuator="J_F1_R1" />
    <actuatorvel name="J_F1_R1_v" actuator="J_F1_R1" />
    <actuatorfrc name="J_F1_R1_f" actuator="J_F1_R1" noise="0.001" />
    <actuatorpos name="J_F1_R2_p" actuator="J_F1_R2" />
    <actuatorvel name="J_F1_R2_v" actuator="J_F1_R2" />
    <actuatorfrc name="J_F1_R2_f" actuator="J_F1_R2" noise="0.001" />
    <actuatorpos name="J_F2_R0_p" actuator="J_F2_R0" />
    <actuatorvel name="J_F2_R0_v" actuator="J_F2_R0" />
    <actuatorfrc name="J_F2_R0_f" actuator="J_F2_R0" noise="0.001" />
    <actuatorpos name="J_F2_R1_p" actuator="J_F2_R1" />
    <actuatorvel name="J_F2_R1_v" actuator="J_F2_R1" />
    <actuatorfrc name="J_F2_R1_f" actuator="J_F2_R1" noise="0.001" />
    <actuatorpos name="J_F2_R2_p" actuator="J_F2_R2" />
    <actuatorvel name="J_F2_R2_v" actuator="J_F2_R2" />
    <actuatorfrc name="J_F2_R2_f" actuator="J_F2_R2" noise="0.001" />
  </sensor>
</mujoco>
