<!-- humanoid_body.xml - 人体模型的主体结构 -->
<mujoco>
    <asset>
        <texture type="skybox" builtin="gradient" rgb1=".3 .5 .7" rgb2="0 0 0" width="32" height="512" />
        <texture name="body" type="cube" builtin="flat" mark="cross" width="128" height="128" rgb1="0.8 0.6 0.4" rgb2="0.8 0.6 0.4" markrgb="1 1 1" random="0.01" />
        <material name="body" texture="body" texuniform="true" rgba="0.8 0.6 .4 1" />
        <texture name="grid" type="2d" builtin="checker" width="512" height="512" rgb1=".1 .2 .3" rgb2=".2 .3 .4" />
        <material name="grid" texture="grid" texrepeat="1 1" texuniform="true" reflectance=".2" />
    </asset>

    <worldbody>

        <!-- <geom name="floor" size="0 0 .05" type="plane" material="grid" condim="1" /> -->
        <!-- <light name="spotlight" mode="targetbodycom" target="torso" diffuse=".8 .8 .8"
            specular="0.3 0.3 0.3" pos="0 -6 4" cutoff="30" /> -->

        <body name="torso" pos="0.6 0 1.282" childclass="body" quat="0 0 0 1">
        <!-- <body name="torso" pos="0 0 1.282" childclass="body"> -->
        <!-- <body name="torso" pos="0 -1 1.282" childclass="body"> -->
            <light name="top" pos="0 0 2" mode="trackcom" />
            <camera name="back" pos="-3 0 1" xyaxes="0 -1 0 1 0 2" mode="trackcom" />
            <camera name="side" pos="0 -3 1" xyaxes="1 0 0 0 1 2" mode="trackcom" />
            <freejoint name="human_root" />
            <geom name="torso" fromto="0 -.07 0 0 .07 0" size=".07" />
            <geom name="waist_upper" fromto="-.01 -.06 -.12 -.01 .06 -.12" size=".06" />
            <body name="head" pos="0 0 .19">
                <geom name="head" type="sphere" size=".09" />
                <camera name="egocentric" pos=".09 0 0" xyaxes="0 -1 0 .1 0 1" fovy="80" />
            </body>
            <body name="waist_lower" pos="-.01 0 -.26">
                <geom name="waist_lower" fromto="0 -.06 0 0 .06 0" size=".06" />
                <joint name="abdomen_z" pos="0 0 .065" axis="0 0 1" range="-45 45" class="joint_big_stiff" />
                <joint name="abdomen_y" pos="0 0 .065" axis="0 1 0" range="-75 30" class="joint_big" />
                <body name="pelvis" pos="0 0 -.165">
                    <joint name="abdomen_x" pos="0 0 .1" axis="1 0 0" range="-35 35" class="joint_big" />
                    <geom name="butt" fromto="-.02 -.07 0 -.02 .07 0" size=".09" />
                    <body name="thigh_right" pos="0 -.1 -.04">
                        <joint name="hip_x_right" axis="1 0 0" class="hip_x" />
                        <joint name="hip_z_right" axis="0 0 1" class="hip_z" />
                        <joint name="hip_y_right" class="hip_y" />
                        <geom name="thigh_right" fromto="0 0 0 0 .01 -.34" class="thigh" />
                        <body name="shin_right" pos="0 .01 -.4">
                            <joint name="knee_right" class="knee" />
                            <geom name="shin_right" class="shin" />
                            <body name="foot_right" pos="0 0 -.39">
                                <joint name="ankle_y_right" class="ankle_y" />
                                <joint name="ankle_x_right" class="ankle_x" axis="1 0 .5" />
                                <geom name="foot1_right" class="foot1" />
                                <geom name="foot2_right" class="foot2" />
                            </body>
                        </body>
                    </body>
                    <body name="thigh_left" pos="0 .1 -.04">
                        <joint name="hip_x_left" axis="-1 0 0" class="hip_x" />
                        <joint name="hip_z_left" axis="0 0 -1" class="hip_z" />
                        <joint name="hip_y_left" class="hip_y" />
                        <geom name="thigh_left" fromto="0 0 0 0 -.01 -.34" class="thigh" />
                        <body name="shin_left" pos="0 -.01 -.4">
                            <joint name="knee_left" class="knee" />
                            <geom name="shin_left" fromto="0 0 0 0 0 -.3" class="shin" />
                            <body name="foot_left" pos="0 0 -.39">
                                <joint name="ankle_y_left" class="ankle_y" />
                                <joint name="ankle_x_left" class="ankle_x" axis="-1 0 -.5" />
                                <geom name="foot1_left" class="foot1" />
                                <geom name="foot2_left" class="foot2" />
                            </body>
                        </body>
                    </body>
                </body>
            </body>
            <body name="upper_arm_right" pos="0 -.17 .06">
                <joint name="shoulder1_right" axis="2 1 1" class="shoulder" />
                <joint name="shoulder2_right" axis="0 -1 1" class="shoulder" />
                <geom name="upper_arm_right" fromto="0 0 0 .16 -.16 -.16" class="arm_upper" />
                <body name="lower_arm_right" pos=".18 -.18 -.18">
                    <joint name="elbow_right" axis="0 -1 1" class="elbow" />
                    <geom name="lower_arm_right" fromto=".01 .01 .01 .17 .17 .17" class="arm_lower" />
                    <body name="hand_right" pos=".18 .18 .18">
                        <geom name="hand_right" zaxis="1 1 1" class="hand" />
                    </body>
                </body>
            </body>
            <body name="upper_arm_left" pos="0 .17 .06">
                <joint name="shoulder1_left" axis="-2 1 -1" class="shoulder" />
                <joint name="shoulder2_left" axis="0 -1 -1" class="shoulder" />
                <geom name="upper_arm_left" fromto="0 0 0 .16 .16 -.16" class="arm_upper" />
                <body name="lower_arm_left" pos=".18 .18 -.18">
                    <joint name="elbow_left" axis="0 -1 -1" class="elbow" />
                    <geom name="lower_arm_left" fromto=".01 -.01 .01 .17 -.17 .17" class="arm_lower" />
                    <body name="hand_left" pos=".18 -.18 .18">
                        <geom name="hand_left" zaxis="1 -1 1" class="hand" />
                    </body>
                </body>
            </body>
        </body>

    </worldbody>

</mujoco>