<?xml version="1.0" encoding="utf-8"?>
<!-- This URDF was automatically created by SolidWorks to URDF Exporter! Originally created by Stephen Brawner (brawner@gmail.com) 
     Commit Version: 1.6.0-4-g7f85cfe  Build Version: 1.6.7995.38578
     For more information, please see http://wiki.ros.org/sw_urdf_exporter -->
<robot name="the_six">
  <link name="world"/>
  <link name="BASE_X">
    <inertial>
      <origin xyz="0 0 0" rpy="0 0 0" />
      <mass value="0.01" />
      <inertia 
        ixx="0.000001"
        ixy="0"
        ixz="0"
        iyy="0.000001"
        iyz="0"
        izz="0.000001" />
    </inertial>
  </link>
  <link name="BASE_Y">
    <inertial>
      <origin xyz="0 0 0" rpy="0 0 0" />
      <mass value="0.01" />
      <inertia 
        ixx="0.000001"
        ixy="0"
        ixz="0"
        iyy="0.000001"
        iyz="0"
        izz="0.000001" />
    </inertial>
  </link>
  <joint name="J_BASE_X" type="prismatic">
    <origin xyz="0 0 0" rpy="0 0 0" />
    <parent link="world" />
    <child link="BASE_X" />
    <axis xyz="1 0 0" />
    <limit
      lower="-10"
      upper="10"
      effort="5000"
      velocity="10" />
  </joint>
  <joint name="J_BASE_Y" type="prismatic">
    <origin xyz="0 0 0" rpy="0 0 0" />
    <parent link="BASE_X" />
    <child link="BASE_Y" />
    <axis xyz="0 1 0" />
    <limit
      lower="-10"
      upper="10"
      effort="5000"
      velocity="10" />
  </joint>
  <joint name="J_BASE_YAW" type="revolute">
    <origin xyz="0 0 0" rpy="0 0 0" />
    <parent link="BASE_Y" />
    <child link="LINK_BASE" />
    <axis xyz="0 0 1" />
    <limit
      lower="-1000000"
      upper="1000000"
      effort="5000"
      velocity="10" />
  </joint>

<!-- robot waist and head -->
  <link name="LINK_BASE">
    <inertial>
      <origin xyz="-0.012524 0.000043 0.266752" rpy="0 0 0" />
      <mass value="283.15" />
      <inertia 
        ixx="10.866143"
        ixy="-0.206807"
        ixz="0.304737"
        iyy="15.449154"
        iyz="0.014934"
        izz="9.558096" />
    </inertial>
    <visual>
      <origin xyz="0 0 0" rpy="0 0 0" />
      <geometry>
        <mesh filename="package://sim_robot/urdf/meshes/LINK_BASE.STL" />
      </geometry>
      <material name="">
        <color rgba="0.7 0.7 0.7 1" />
      </material>
    </visual>
    <collision>
      <origin xyz="0 0 0" rpy="0 0 0" />
      <geometry>
        <mesh filename="package://sim_robot/urdf/meshes/LINK_BASE.STL" />
      </geometry>
    </collision>
  </link>
  <link name="LINK_WAIST_M0">
    <inertial>
      <origin xyz="0.060889 -0.000663 0.206273" rpy="0 0 0" />
      <mass value="38.14" />
      <inertia
        ixx="3.431328"
        ixy="0.000123"
        ixz="0.781903"
        iyy="3.644659"
        iyz="-0.005351"
        izz="0.601610" />
    </inertial>
    <visual>
      <origin xyz="0 0 0" rpy="0 0 0" />
      <geometry>
        <mesh filename="package://sim_robot/urdf/meshes/LINK_WAIST_M0.STL" />
      </geometry>
      <material name="">
        <color rgba="0.7 0.7 0.7 1" />
      </material>
    </visual>
    <collision>
      <origin
        xyz="0 0 0"
        rpy="0 0 0" />
      <geometry>
        <mesh
          filename="package://sim_robot/urdf/meshes/LINK_WAIST_M0.STL" />
      </geometry>
    </collision>
  </link>
  <joint name="J_WAIST_M0" type="prismatic">
    <origin xyz="0.2994 0 0.9045" rpy="0 0 0" />
    <parent link="LINK_BASE" />
    <child link="LINK_WAIST_M0" />
    <axis xyz="0 0 1" />
    <limit
      lower="-0.3"
      upper="0"
      effort="1000"
      velocity="1" />
  </joint>
  <link name="LINK_NECK_M0">
    <inertial>
      <origin xyz="0.000314 0.000456 0.042045" rpy="0 0 0" />
      <mass value="0.953" />
      <inertia
        ixx="0.000695"
        ixy="0"
        ixz="-0.000003"
        iyy="0.000688"
        iyz="0.000003"
        izz="0.000642" />
    </inertial>
    <visual>
      <origin xyz="0 0 0" rpy="0 0 0" />
      <geometry>
        <mesh filename="package://sim_robot/urdf/meshes/LINK_NECK_M0.STL" />
      </geometry>
      <material name="">
        <color rgba="0.7 0.7 0.7 1" />
      </material>
    </visual>
    <collision>
      <origin xyz="0 0 0" rpy="0 0 0" />
      <geometry>
        <mesh filename="package://sim_robot/urdf/meshes/LINK_NECK_M0.STL" />
      </geometry>
    </collision>
  </link>
  <joint name="J_NECK_M0" type="revolute">
    <origin xyz="0.162 0 0.611" rpy="0 0 0" />
    <parent link="LINK_WAIST_M0" />
    <child link="LINK_NECK_M0" />
    <axis xyz="0 0 1" />
    <limit
      lower="-2.9322"
      upper="2.9322"
      effort="19"
      velocity="3.1416" />
  </joint>
  <link name="LINK_NECK_M1">
    <inertial>
      <origin xyz="-0.003110 -0.118218 -0.000205" rpy="0 0 0" />
      <mass value="0.648" />
      <inertia
        ixx="0.001546"
        ixy="-0.000098"
        ixz="0.000013"
        iyy="0.001290"
        iyz="-0.000014"
        izz="0.000864" />
    </inertial>
    <visual>
      <origin xyz="0 0 0" rpy="0 0 0" />
      <geometry>
        <mesh filename="package://sim_robot/urdf/meshes/LINK_NECK_M1.STL" />
      </geometry>
      <material name="">
        <color rgba="0.7 0.7 0.7 1" />
      </material>
    </visual>
    <collision>
      <origin xyz="0 0 0" rpy="0 0 0" />
      <geometry>
        <mesh filename="package://sim_robot/urdf/meshes/LINK_NECK_M1.STL" />
      </geometry>
    </collision>
  </link>
  <joint name="J_NECK_M1" type="revolute">
    <origin xyz="0 0 0.044" rpy="-1.5708 0 0" />
    <parent link="LINK_NECK_M0" />
    <child link="LINK_NECK_M1" />
    <axis xyz="0 0 1" />
    <limit
      lower="-0.0524"
      upper="1.2741"
      effort="19"
      velocity="3.1416" />
  </joint>

<!-- left arm -->
  <link name="LINK_ARM_BASE_L">
    <inertial>
      <origin
        xyz="8.8e-05 -0.003875 0.000102"
        rpy="0 0 0" />
      <mass
        value="0.98605" />
      <inertia
        ixx="0.000525"
        ixy="3e-06"
        ixz="2e-06"
        iyy="0.000568"
        iyz="9e-06"
        izz="0.00052" />
    </inertial>
    <visual>
      <origin
        xyz="0 0 0"
        rpy="0 0 0" />
      <geometry>
        <mesh
          filename="package://sim_robot/urdf/meshes/LINK_BASE_L.STL" />
      </geometry>
      <material
        name="">
        <color
          rgba="0.7 0.7 0.7 1" />
      </material>
    </visual>
    <collision>
      <origin
        xyz="0 0 0"
        rpy="0 0 0" />
      <geometry>
        <mesh
          filename="package://sim_robot/urdf/meshes/LINK_BASE_L.STL" />
      </geometry>
    </collision>
  </link>
  <joint name="J_ARM_BASE_L" type="fixed">
    <origin xyz="0.172 0.096 0.539" rpy="0 0 0" />
    <parent link="LINK_WAIST_M0" />
    <child link="LINK_ARM_BASE_L" />
  </joint>
  <link name="LINK_SHOULDER_L0">
    <inertial>
      <origin
        xyz="-0.002053 0.000827 -0.012825"
        rpy="0 0 0" />
      <mass
        value="0.2392" />
      <inertia
        ixx="0.000132"
        ixy="1e-06"
        ixz="6e-06"
        iyy="0.000145"
        iyz="-1e-06"
        izz="9e-05" />
    </inertial>
    <visual>
      <origin
        xyz="0 0 0"
        rpy="0 0 0" />
      <geometry>
        <mesh
          filename="package://sim_robot/urdf/meshes/LINK_SHOULDER_L0.STL" />
      </geometry>
      <material
        name="">
        <color
          rgba="0.7 0.7 0.7 1" />
      </material>
    </visual>
    <collision>
      <origin
        xyz="0 0 0"
        rpy="0 0 0" />
      <geometry>
        <mesh
          filename="package://sim_robot/urdf/meshes/LINK_SHOULDER_L0.STL" />
      </geometry>
    </collision>
  </link>
  <joint name="J_SHOULDER_L0" type="revolute">
    <origin
      xyz="0 0.06895 0"
      rpy="-1.5708 1.5708 0" />
    <parent
      link="LINK_ARM_BASE_L" />
    <child
      link="LINK_SHOULDER_L0" />
    <axis
      xyz="0 0 1" />
    <limit
      lower="-2.8798"
      upper="1.0472"
      effort="117"
      velocity="9.425" />
  </joint>
  <link name="LINK_SHOULDER_L1">
    <inertial>
      <origin
        xyz="0.044196 0.021385 -0.01858"
        rpy="0 0 0" />
      <mass
        value="1.7672" />
      <inertia
        ixx="0.00253"
        ixy="0.001415"
        ixz="0.001453"
        iyy="0.004826"
        iyz="0.000715"
        izz="0.004542" />
    </inertial>
    <visual>
      <origin
        xyz="0 0 0"
        rpy="0 0 0" />
      <geometry>
        <mesh
          filename="package://sim_robot/urdf/meshes/LINK_SHOULDER_L1.STL" />
      </geometry>
      <material
        name="">
        <color
          rgba="0.7 0.7 0.7 1" />
      </material>
    </visual>
    <collision>
      <origin
        xyz="0 0 0"
        rpy="0 0 0" />
      <geometry>
        <mesh
          filename="package://sim_robot/urdf/meshes/LINK_SHOULDER_L1.STL" />
      </geometry>
    </collision>
  </link>
  <joint name="J_SHOULDER_L1" type="revolute">
    <origin
      xyz="0 0 0"
      rpy="1.5708 0 0" />
    <parent
      link="LINK_SHOULDER_L0" />
    <child
      link="LINK_SHOULDER_L1" />
    <axis
      xyz="0 0 1" />
    <limit
      lower="-0.5236"
      upper="2.4434"
      effort="117"
      velocity="9.425" />
  </joint>
  <link name="LINK_SHOULDER_L2">
    <inertial>
      <origin
        xyz="2e-06 0.007424 0.1136"
        rpy="0 0 0" />
      <mass
        value="1.6352" />
      <inertia
        ixx="0.007208"
        ixy="-3.7e-05"
        ixz="-0.000168"
        iyy="0.007287"
        iyz="0.000268"
        izz="0.00128" />
    </inertial>
    <visual>
      <origin
        xyz="0 0 0"
        rpy="0 0 0" />
      <geometry>
        <mesh
          filename="package://sim_robot/urdf/meshes/LINK_SHOULDER_L2.STL" />
      </geometry>
      <material
        name="">
        <color
          rgba="0.7 0.7 0.7 1" />
      </material>
    </visual>
    <collision>
      <origin
        xyz="0 0 0"
        rpy="0 0 0" />
      <geometry>
        <mesh
          filename="package://sim_robot/urdf/meshes/LINK_SHOULDER_L2.STL" />
      </geometry>
    </collision>
  </link>
  <joint name="J_SHOULDER_L2" type="revolute">
    <origin
      xyz="0.1035 0.04 0"
      rpy="0 1.5708 0" />
    <parent
      link="LINK_SHOULDER_L1" />
    <child
      link="LINK_SHOULDER_L2" />
    <axis
      xyz="0 0 1" />
    <limit
      lower="-2.6180"
      upper="2.6180"
      effort="65"
      velocity="9.425" />
  </joint>
  <link name="LINK_ELBOW_L0">
    <inertial>
      <origin
        xyz="0.003887 -0.000124 -0.000164"
        rpy="0 0 0" />
      <mass
        value="0.15153" />
      <inertia
        ixx="0.000127"
        ixy="0"
        ixz="0"
        iyy="0.00014"
        iyz="0"
        izz="2.8e-05" />
    </inertial>
    <visual>
      <origin
        xyz="0 0 0"
        rpy="0 0 0" />
      <geometry>
        <mesh
          filename="package://sim_robot/urdf/meshes/LINK_ELBOW_L0.STL" />
      </geometry>
      <material
        name="">
        <color
          rgba="0.7 0.7 0.7 1" />
      </material>
    </visual>
    <collision>
      <origin
        xyz="0 0 0"
        rpy="0 0 0" />
      <geometry>
        <mesh
          filename="package://sim_robot/urdf/meshes/LINK_ELBOW_L0.STL" />
      </geometry>
    </collision>
  </link>
  <joint name="J_ELBOW_L0" type="revolute">
    <origin
      xyz="0 0 0.2165"
      rpy="0 -1.5708 0" />
    <parent
      link="LINK_SHOULDER_L2" />
    <child
      link="LINK_ELBOW_L0" />
    <axis
      xyz="0 0 1" />
    <limit
      lower="-2.2689"
      upper="0"
      effort="66"
      velocity="23.557" />
  </joint>
  <link name="LINK_ELBOW_L1">
    <inertial>
      <origin
        xyz="-2.9e-05 -0.000267 0.14122"
        rpy="0 0 0" />
      <mass
        value="1.1669" />
      <inertia
        ixx="0.004805"
        ixy="0"
        ixz="1e-06"
        iyy="0.004964"
        iyz="-0.000232"
        izz="0.000575" />
    </inertial>
    <visual>
      <origin
        xyz="0 0 0"
        rpy="0 0 0" />
      <geometry>
        <mesh
          filename="package://sim_robot/urdf/meshes/LINK_ELBOW_L1.STL" />
      </geometry>
      <material
        name="">
        <color
          rgba="0.7 0.7 0.7 1" />
      </material>
    </visual>
    <collision>
      <origin
        xyz="0 0 0"
        rpy="0 0 0" />
      <geometry>
        <mesh
          filename="package://sim_robot/urdf/meshes/LINK_ELBOW_L1.STL" />
      </geometry>
    </collision>
  </link>
  <joint name="J_ELBOW_L1" type="revolute">
    <origin
      xyz="0 0 0"
      rpy="0 1.5708 0" />
    <parent
      link="LINK_ELBOW_L0" />
    <child
      link="LINK_ELBOW_L1" />
    <axis
      xyz="0 0 1" />
    <limit
      lower="-2.3562"
      upper="2.3562"
      effort="66"
      velocity="23.557" />
  </joint>
  <link name="LINK_WRIST_L0">
    <inertial>
      <origin
        xyz="-0.000267 -0.000273 -3.5e-05"
        rpy="0 0 0" />
      <mass
        value="0.075056" />
      <inertia
        ixx="3.6e-05"
        ixy="0"
        ixz="0"
        iyy="3.4e-05"
        iyz="0"
        izz="1.1e-05" />
    </inertial>
    <visual>
      <origin
        xyz="0 0 0"
        rpy="0 0 0" />
      <geometry>
        <mesh
          filename="package://sim_robot/urdf/meshes/LINK_WRIST_L0.STL" />
      </geometry>
      <material
        name="">
        <color
          rgba="0.7 0.7 0.7 1" />
      </material>
    </visual>
    <collision>
      <origin
        xyz="0 0 0"
        rpy="0 0 0" />
      <geometry>
        <mesh
          filename="package://sim_robot/urdf/meshes/LINK_WRIST_L0.STL" />
      </geometry>
    </collision>
  </link>
  <joint name="J_WRIST_L0" type="revolute">
    <origin
      xyz="0 0 0.28"
      rpy="-1.5708 -1.5708 0" />
    <parent
      link="LINK_ELBOW_L1" />
    <child
      link="LINK_WRIST_L0" />
    <axis
      xyz="0 0 1" />
    <limit
      lower="-0.8727"
      upper="0.8727"
      effort="41"
      velocity="37.7" />
  </joint>
  <link name="LINK_WRIST_L1">
    <inertial>
      <origin
        xyz="0.015646 8.1e-05 -0.003649"
        rpy="0 0 0" />
      <mass
        value="0.063853" />
      <inertia
        ixx="3.8e-05"
        ixy="0"
        ixz="3e-06"
        iyy="5.5e-05"
        iyz="0"
        izz="3.1e-05" />
    </inertial>
    <visual>
      <origin
        xyz="0 0 0"
        rpy="0 0 0" />
      <geometry>
        <mesh
          filename="package://sim_robot/urdf/meshes/LINK_WRIST_L1.STL" />
      </geometry>
      <material
        name="">
        <color
          rgba="0.7 0.7 0.7 1" />
      </material>
    </visual>
    <collision>
      <origin
        xyz="0 0 0"
        rpy="0 0 0" />
      <geometry>
        <mesh
          filename="package://sim_robot/urdf/meshes/LINK_WRIST_L1.STL" />
      </geometry>
    </collision>
  </link>
  <joint name="J_WRIST_L1" type="revolute">
    <origin
      xyz="0 0 0"
      rpy="1.5708 0 0" />
    <parent
      link="LINK_WRIST_L0" />
    <child
      link="LINK_WRIST_L1" />
    <axis
      xyz="0 0 1" />
    <limit
      lower="-1.5708"
      upper="1.3963"
      effort="41"
      velocity="37.7" />
  </joint>

<!-- right arm -->
  <link name="LINK_ARM_BASE_R">
    <inertial>
      <origin
        xyz="8.8e-05 0.003875 0.000102"
        rpy="0 0 0" />
      <mass
        value="0.98605" />
      <inertia
        ixx="0.000525"
        ixy="3e-06"
        ixz="2e-06"
        iyy="0.000568"
        iyz="9e-06"
        izz="0.00052" />
    </inertial>
    <visual>
      <origin
        xyz="0 0 0"
        rpy="0 0 0" />
      <geometry>
        <mesh
          filename="package://sim_robot/urdf/meshes/LINK_BASE_R.STL" />
      </geometry>
      <material
        name="">
        <color
          rgba="0.7 0.7 0.7 1" />
      </material>
    </visual>
    <collision>
      <origin
        xyz="0 0 0"
        rpy="0 0 0" />
      <geometry>
        <mesh
          filename="package://sim_robot/urdf/meshes/LINK_BASE_R.STL" />
      </geometry>
    </collision>
  </link>
  <joint name="J_ARM_BASE_R" type="fixed">
    <origin xyz="0.172 -0.096 0.539" rpy="0 0 0" />
    <parent link="LINK_WAIST_M0" />
    <child link="LINK_ARM_BASE_R" />
  </joint>
  <link name="LINK_SHOULDER_R0">
    <inertial>
      <origin
        xyz="-0.002053 0.000827 0.012825"
        rpy="0 0 0" />
      <mass
        value="0.2392" />
      <inertia
        ixx="0.000132"
        ixy="1e-06"
        ixz="6e-06"
        iyy="0.000145"
        iyz="-1e-06"
        izz="9e-05" />
    </inertial>
    <visual>
      <origin
        xyz="0 0 0"
        rpy="0 0 0" />
      <geometry>
        <mesh
          filename="package://sim_robot/urdf/meshes/LINK_SHOULDER_R0.STL" />
      </geometry>
      <material
        name="">
        <color
          rgba="0.7 0.7 0.7 1" />
      </material>
    </visual>
    <collision>
      <origin
        xyz="0 0 0"
        rpy="0 0 0" />
      <geometry>
        <mesh
          filename="package://sim_robot/urdf/meshes/LINK_SHOULDER_R0.STL" />
      </geometry>
    </collision>
  </link>
  <joint name="J_SHOULDER_R0" type="revolute">
    <origin
      xyz="0 -0.06895 0"
      rpy="-1.5708 1.5708 0" />
    <parent
      link="LINK_ARM_BASE_R" />
    <child
      link="LINK_SHOULDER_R0" />
    <axis
      xyz="0 0 1" />
    <limit
      lower="-2.8798"
      upper="1.0472"
      effort="117"
      velocity="9.425" />
  </joint>
  <link name="LINK_SHOULDER_R1">
    <inertial>
      <origin
        xyz="0.044196 -0.021385 -0.01858"
        rpy="0 0 0" />
      <mass
        value="1.7672" />
      <inertia
        ixx="0.00253"
        ixy="0.001415"
        ixz="0.001453"
        iyy="0.004826"
        iyz="0.000715"
        izz="0.004542" />
    </inertial>
    <visual>
      <origin
        xyz="0 0 0"
        rpy="0 0 0" />
      <geometry>
        <mesh
          filename="package://sim_robot/urdf/meshes/LINK_SHOULDER_R1.STL" />
      </geometry>
      <material
        name="">
        <color
          rgba="0.7 0.7 0.7 1" />
      </material>
    </visual>
    <collision>
      <origin
        xyz="0 0 0"
        rpy="0 0 0" />
      <geometry>
        <mesh
          filename="package://sim_robot/urdf/meshes/LINK_SHOULDER_R1.STL" />
      </geometry>
    </collision>
  </link>
  <joint name="J_SHOULDER_R1" type="revolute">
    <origin
      xyz="0 0 0"
      rpy="1.5708 0 0" />
    <parent
      link="LINK_SHOULDER_R0" />
    <child
      link="LINK_SHOULDER_R1" />
    <axis
      xyz="0 0 1" />
    <limit
      lower="-2.4434"
      upper="0.5236"
      effort="117"
      velocity="9.425" />
  </joint>
  <link name="LINK_SHOULDER_R2">
    <inertial>
      <origin
        xyz="2e-06 -0.007424 0.1136"
        rpy="0 0 0" />
      <mass
        value="1.6352" />
      <inertia
        ixx="0.007208"
        ixy="-3.7e-05"
        ixz="-0.000168"
        iyy="0.007287"
        iyz="0.000268"
        izz="0.00128" />
    </inertial>
    <visual>
      <origin
        xyz="0 0 0"
        rpy="0 0 0" />
      <geometry>
        <mesh
          filename="package://sim_robot/urdf/meshes/LINK_SHOULDER_R2.STL" />
      </geometry>
      <material
        name="">
        <color
          rgba="0.7 0.7 0.7 1" />
      </material>
    </visual>
    <collision>
      <origin
        xyz="0 0 0"
        rpy="0 0 0" />
      <geometry>
        <mesh
          filename="package://sim_robot/urdf/meshes/LINK_SHOULDER_R2.STL" />
      </geometry>
    </collision>
  </link>
  <joint name="J_SHOULDER_R2" type="revolute">
    <origin
      xyz="0.1035 -0.04 0"
      rpy="0 1.5708 0" />
    <parent
      link="LINK_SHOULDER_R1" />
    <child
      link="LINK_SHOULDER_R2" />
    <axis
      xyz="0 0 1" />
    <limit
      lower="-2.6180"
      upper="2.6180"
      effort="65"
      velocity="9.425" />
  </joint>
  <link name="LINK_ELBOW_R0">
    <inertial>
      <origin
        xyz="0.003887 0.000124 -0.000164"
        rpy="0 0 0" />
      <mass
        value="0.15153" />
      <inertia
        ixx="0.000127"
        ixy="0"
        ixz="0"
        iyy="0.00014"
        iyz="0"
        izz="2.8e-05" />
    </inertial>
    <visual>
      <origin
        xyz="0 0 0"
        rpy="0 0 0" />
      <geometry>
        <mesh
          filename="package://sim_robot/urdf/meshes/LINK_ELBOW_R0.STL" />
      </geometry>
      <material
        name="">
        <color
          rgba="0.7 0.7 0.7 1" />
      </material>
    </visual>
    <collision>
      <origin
        xyz="0 0 0"
        rpy="0 0 0" />
      <geometry>
        <mesh
          filename="package://sim_robot/urdf/meshes/LINK_ELBOW_R0.STL" />
      </geometry>
    </collision>
  </link>
  <joint name="J_ELBOW_R0" type="revolute">
    <origin
      xyz="0 0 0.2165"
      rpy="0 -1.5708 0" />
    <parent
      link="LINK_SHOULDER_R2" />
    <child
      link="LINK_ELBOW_R0" />
    <axis
      xyz="0 0 1" />
    <limit
      lower="0"
      upper="2.2689"
      effort="66"
      velocity="23.557" />
  </joint>
  <link name="LINK_ELBOW_R1">
    <inertial>
      <origin
        xyz="-2.9e-05 0.000267 0.14122"
        rpy="0 0 0" />
      <mass
        value="1.1669" />
      <inertia
        ixx="0.004805"
        ixy="0"
        ixz="1e-06"
        iyy="0.004964"
        iyz="-0.000232"
        izz="0.000575" />
    </inertial>
    <visual>
      <origin
        xyz="0 0 0"
        rpy="0 0 0" />
      <geometry>
        <mesh
          filename="package://sim_robot/urdf/meshes/LINK_ELBOW_R1.STL" />
      </geometry>
      <material
        name="">
        <color
          rgba="0.7 0.7 0.7 1" />
      </material>
    </visual>
    <collision>
      <origin
        xyz="0 0 0"
        rpy="0 0 0" />
      <geometry>
        <mesh
          filename="package://sim_robot/urdf/meshes/LINK_ELBOW_R1.STL" />
      </geometry>
    </collision>
  </link>
  <joint name="J_ELBOW_R1"
    type="revolute">
    <origin
      xyz="0 0 0"
      rpy="0 1.5708 0" />
    <parent
      link="LINK_ELBOW_R0" />
    <child
      link="LINK_ELBOW_R1" />
    <axis
      xyz="0 0 1" />
    <limit
      lower="-2.3562"
      upper="2.3562"
      effort="66"
      velocity="23.557" />
  </joint>
  <link name="LINK_WRIST_R0">
    <inertial>
      <origin
        xyz="-0.000267 -0.000273 3.5e-05"
        rpy="0 0 0" />
      <mass
        value="0.075056" />
      <inertia
        ixx="3.6e-05"
        ixy="0"
        ixz="0"
        iyy="3.4e-05"
        iyz="0"
        izz="1.1e-05" />
    </inertial>
    <visual>
      <origin
        xyz="0 0 0"
        rpy="0 0 0" />
      <geometry>
        <mesh
          filename="package://sim_robot/urdf/meshes/LINK_WRIST_R0.STL" />
      </geometry>
      <material
        name="">
        <color
          rgba="0.7 0.7 0.7 1" />
      </material>
    </visual>
    <collision>
      <origin
        xyz="0 0 0"
        rpy="0 0 0" />
      <geometry>
        <mesh
          filename="package://sim_robot/urdf/meshes/LINK_WRIST_R0.STL" />
      </geometry>
    </collision>
  </link>
  <joint name="J_WRIST_R0" type="revolute">
    <origin
      xyz="0 0 0.28"
      rpy="-1.5708 -1.5708 0" />
    <parent
      link="LINK_ELBOW_R1" />
    <child
      link="LINK_WRIST_R0" />
    <axis
      xyz="0 0 1" />
    <limit
      lower="-0.8727"
      upper="0.8727"
      effort="41"
      velocity="37.7" />
  </joint>
  <link name="LINK_WRIST_R1">
    <inertial>
      <origin
        xyz="0.015646 -8.1e-05 -0.003649"
        rpy="0 0 0" />
      <mass
        value="0.063853" />
      <inertia
        ixx="3.8e-05"
        ixy="0"
        ixz="3e-06"
        iyy="5.5e-05"
        iyz="0"
        izz="3.1e-05" />
    </inertial>
    <visual>
      <origin
        xyz="0 0 0"
        rpy="0 0 0" />
      <geometry>
        <mesh
          filename="package://sim_robot/urdf/meshes/LINK_WRIST_R1.STL" />
      </geometry>
      <material
        name="">
        <color
          rgba="0.7 0.7 0.7 1" />
      </material>
    </visual>
    <collision>
      <origin
        xyz="0 0 0"
        rpy="0 0 0" />
      <geometry>
        <mesh
          filename="package://sim_robot/urdf/meshes/LINK_WRIST_R1.STL" />
      </geometry>
    </collision>
  </link>
  <joint name="J_WRIST_R1" type="revolute">
    <origin
      xyz="0 0 0"
      rpy="1.5708 0 0" />
    <parent
      link="LINK_WRIST_R0" />
    <child
      link="LINK_WRIST_R1" />
    <axis
      xyz="0 0 1" />
    <limit
      lower="-1.3963"
      upper="1.5708"
      effort="41"
      velocity="37.7" />
  </joint>

<!-- left hand -->
  <link name="LINK_HAND_BASE_L">
    <inertial>
      <origin xyz="0.048419 -0.004068 0.000167" rpy="0 0 0" />
      <mass value="0.5804" />
      <inertia
        ixx="0.0004471"
        ixy="0.00002308"
        ixz="-0.00004840"
        iyy="0.00056348"
        iyz="-0.00002031"
        izz="0.00074463" />
    </inertial>
    <visual>
      <origin xyz="0 0 0" rpy="0 0 0" />
      <geometry>
        <mesh filename="package://sim_robot/urdf/meshes/LINK_HAND_BASE_L.STL" />
      </geometry>
      <material name="">
        <color rgba="0.7 0.7 0.7 1" />
      </material>
    </visual>
    <collision>
      <origin xyz="0 0 0" rpy="0 0 0" />
      <geometry>
        <mesh filename="package://sim_robot/urdf/meshes/LINK_HAND_BASE_L.STL" />
      </geometry>
    </collision>
  </link>
  <joint name="J_HAND_BASE_L" type="fixed">
    <origin xyz="0.0555 0 0" rpy="1.5708 0 0" />
    <parent link="LINK_WRIST_L1" />
    <child link="LINK_HAND_BASE_L" />
  </joint>
  <link name="LINK_F0_L0">
    <inertial>
      <origin xyz="-0.00003617 0.00000000 -0.00084515" rpy="0 0 0" />
      <mass value="0.026087" />
      <inertia
        ixx="0.00000192"
        ixy="0"
        ixz="0"
        iyy="0.00000152"
        iyz="0"
        izz="0.00000122" />
    </inertial>
    <visual>
      <origin xyz="0 0 0" rpy="0 0 0" />
      <geometry>
        <mesh filename="package://sim_robot/urdf/meshes/LINK_F0_L0.STL" />
      </geometry>
      <material name="">
        <color rgba="0.7 0.7 0.7 1" />
      </material>
    </visual>
    <collision>
      <origin xyz="0 0 0" rpy="0 0 0" />
      <geometry>
        <mesh filename="package://sim_robot/urdf/meshes/LINK_F0_L0.STL" />
      </geometry>
    </collision>
  </link>
  <joint name="J_F0_L0" type="revolute">
    <origin xyz="0.021499 0.0225 0.020865" rpy="1.5708 0 1.5708" />
    <parent link="LINK_HAND_BASE_L" />
    <child link="LINK_F0_L0" />
    <axis xyz="0 0 1" />
    <limit
      lower="0"
      upper="1.9199"
      effort="3"
      velocity="25" />
  </joint>
  <link name="LINK_F0_L1">
    <inertial>
      <origin xyz="0.03750623 -0.00008894 0.00016480" rpy="0 0 0" />
      <mass value="0.06888161" />
      <inertia
        ixx="0.00000650"
        ixy="-0.00000013"
        ixz="-0.00000001"
        iyy="0.00002055"
        iyz="-0.00000003"
        izz="0.00002001" />
    </inertial>
    <visual>
      <origin xyz="0 0 0" rpy="0 0 0" />
      <geometry>
        <mesh filename="package://sim_robot/urdf/meshes/LINK_F0_L1.STL" />
      </geometry>
      <material name="">
        <color rgba="0.7 0.7 0.7 1" />
      </material>
    </visual>
    <collision>
      <origin xyz="0 0 0" rpy="0 0 0" />
      <geometry>
        <mesh filename="package://sim_robot/urdf/meshes/LINK_F0_L1.STL" />
      </geometry>
    </collision>
  </link>
  <joint name="J_F0_L1" type="revolute">
    <origin xyz="0 0 0" rpy="1.5708 0 0" />
    <parent link="LINK_F0_L0" />
    <child link="LINK_F0_L1" />
    <axis xyz="0 0 1" />
    <limit
      lower="-0.1745"
      upper="0.7854"
      effort="3"
      velocity="25" />
  </joint>
  <link name="LINK_F0_L2">
    <inertial>
      <origin xyz="0.02089747 -0.00213483 -0.00106078" rpy="0 0 0" />
      <mass value="0.03102375" />
      <inertia
        ixx="0.00000240"
        ixy="-0.00000010"
        ixz="0.00000057"
        iyy="0.00000708"
        iyz="-0.00000004"
        izz="0.00000642" />
    </inertial>
    <visual>
      <origin xyz="0 0 0" rpy="0 0 0" />
      <geometry>
        <mesh filename="package://sim_robot/urdf/meshes/LINK_F0_L2.STL" />
      </geometry>
      <material name="">
        <color rgba="0.7 0.7 0.7 1" />
      </material>
    </visual>
    <collision>
      <origin xyz="0 0 0" rpy="0 0 0" />
      <geometry>
        <mesh filename="package://sim_robot/urdf/meshes/LINK_F0_L2.STL" />
      </geometry>
    </collision>
  </link>
  <joint name="J_F0_L2" type="revolute">
    <origin xyz="0.05425 0 0" rpy="0 0 0" />
    <parent link="LINK_F0_L1" />
    <child link="LINK_F0_L2" />
    <axis xyz="0 0 1" />
    <limit
      lower="-0.4363"
      upper="1.5708"
      effort="1.5"
      velocity="25" />
  </joint>
  <link name="LINK_F1_L0">
    <inertial>
      <origin xyz="0.00003617 0 0.00084515" rpy="0 0 0" />
      <mass value="0.026087" />
      <inertia
        ixx="0.00000192"
        ixy="0"
        ixz="0"
        iyy="0.00000152"
        iyz="0"
        izz="0.00000122" />
    </inertial>
    <visual>
      <origin xyz="0 0 0" rpy="0 0 0" />
      <geometry>
        <mesh filename="package://sim_robot/urdf/meshes/LINK_F1_L0.STL" />
      </geometry>
      <material name="">
        <color rgba="0.7 0.7 0.7 1" />
      </material>
    </visual>
    <collision>
      <origin xyz="0 0 0" rpy="0 0 0" />
      <geometry>
        <mesh filename="package://sim_robot/urdf/meshes/LINK_F1_L0.STL" />
      </geometry>
    </collision>
  </link>
  <joint name="J_F1_L0" type="revolute">
    <origin xyz="0.10232 0.0225 0.00574" rpy="1.5708 0 0" />
    <parent link="LINK_HAND_BASE_L" />
    <child link="LINK_F1_L0" />
    <axis xyz="0 0 1" />
    <limit
      lower="-0.4363"
      upper="1.8326"
      effort="3"
      velocity="25" />
  </joint>
  <link name="LINK_F1_L1">
    <inertial>
      <origin xyz="0.03243751 -0.00016602 -0.00016480" rpy="0 0 0" />
      <mass value="0.07027318" />
      <inertia
        ixx="0.00000696"
        ixy="0.00000002"
        ixz="-0.00000005"
        iyy="0.00001858"
        iyz="0.00000003"
        izz="0.00001779" />
    </inertial>
    <visual>
      <origin xyz="0 0 0" rpy="0 0 0" />
      <geometry>
        <mesh filename="package://sim_robot/urdf/meshes/LINK_F1_L1.STL" />
      </geometry>
      <material name="">
        <color rgba="0.7 0.7 0.7 1" />
      </material>
    </visual>
    <collision>
      <origin xyz="0 0 0" rpy="0 0 0" />
      <geometry>
        <mesh filename="package://sim_robot/urdf/meshes/LINK_F1_L1.STL" />
      </geometry>
    </collision>
  </link>
  <joint name="J_F1_L1" type="revolute">
    <origin xyz="0 0 0" rpy="-1.5708 0 0" />
    <parent link="LINK_F1_L0" />
    <child link="LINK_F1_L1" />
    <axis xyz="0 0 1" />
    <limit
      lower="-0.4363"
      upper="0.4363"
      effort="3"
      velocity="25" />
  </joint>
  <link name="LINK_F1_L2">
    <inertial>
      <origin xyz="0.02080647 -0.00102362 -0.00132199" rpy="0 0 0" />
      <mass value="0.02575183" />
      <inertia
        ixx="0.00000205"
        ixy="0.00000013"
        ixz="0.00000055"
        iyy="0.00000636"
        iyz="-0.00000001"
        izz="0.00000573" />
    </inertial>
    <visual>
      <origin xyz="0 0 0" rpy="0 0 0" />
      <geometry>
        <mesh filename="package://sim_robot/urdf/meshes/LINK_F1_L2.STL" />
      </geometry>
      <material name="">
        <color rgba="0.7 0.7 0.7 1" />
      </material>
    </visual>
    <collision>
      <origin xyz="0 0 0" rpy="0 0 0" />
      <geometry>
        <mesh filename="package://sim_robot/urdf/meshes/LINK_F1_L2.STL" />
      </geometry>
    </collision>
  </link>
  <joint name="J_F1_L2" type="revolute">
    <origin xyz="0.04825 0 0" rpy="1.5708 0 0" />
    <parent link="LINK_F1_L1" />
    <child link="LINK_F1_L2" />
    <axis xyz="0 0 1" />
    <limit
      lower="-0.4363"
      upper="1.5708"
      effort="1.5"
      velocity="25" />
  </joint>
  <link name="LINK_F2_L0">
    <inertial>
      <origin xyz="0.00003617 0 0.00084515" rpy="0 0 0" />
      <mass value="0.026087" />
      <inertia
        ixx="0.00000192"
        ixy="0"
        ixz="0"
        iyy="0.00000152"
        iyz="0"
        izz="0.00000122" />
    </inertial>
    <visual>
      <origin xyz="0 0 0" rpy="0 0 0" />
      <geometry>
        <mesh filename="package://sim_robot/urdf/meshes/LINK_F2_L0.STL" />
      </geometry>
      <material name="">
        <color rgba="0.7 0.7 0.7 1" />
      </material>
    </visual>
    <collision>
      <origin xyz="0 0 0" rpy="0 0 0" />
      <geometry>
        <mesh filename="package://sim_robot/urdf/meshes/LINK_F2_L0.STL" />
      </geometry>
    </collision>
  </link>
  <joint name="J_F2_L0" type="revolute">
    <origin xyz="0.10232 -0.0225 0.00574" rpy="1.5708 0 0" />
    <parent link="LINK_HAND_BASE_L" />
    <child link="LINK_F2_L0" />
    <axis xyz="0 0 1" />
    <limit
      lower="-0.4363"
      upper="1.8326"
      effort="3"
      velocity="25" />
  </joint>
  <link name="LINK_F2_L1">
    <inertial>
      <origin xyz="0.03243751 -0.00016602 -0.00016480" rpy="0 0 0" />
      <mass value="0.07027318" />
      <inertia
        ixx="0.00000696"
        ixy="0.00000002"
        ixz="-0.00000005"
        iyy="0.00001858"
        iyz="0.00000003"
        izz="0.00001779" />
    </inertial>
    <visual>
      <origin xyz="0 0 0" rpy="0 0 0" />
      <geometry>
        <mesh filename="package://sim_robot/urdf/meshes/LINK_F2_L1.STL" />
      </geometry>
      <material name="">
        <color rgba="0.7 0.7 0.7 1" />
      </material>
    </visual>
    <collision>
      <origin xyz="0 0 0" rpy="0 0 0" />
      <geometry>
        <mesh filename="package://sim_robot/urdf/meshes/LINK_F2_L1.STL" />
      </geometry>
    </collision>
  </link>
  <joint name="J_F2_L1" type="revolute">
    <origin xyz="0 0 0" rpy="-1.5708 0 0" />
    <parent link="LINK_F2_L0" />
    <child link="LINK_F2_L1" />
    <axis xyz="0 0 1" />
    <limit
      lower="-0.4363"
      upper="0.4363"
      effort="3"
      velocity="25" />
  </joint>
  <link name="LINK_F2_L2">
    <inertial>
      <origin xyz="0.02080647 -0.00102362 -0.00132199" rpy="0 0 0" />
      <mass value="0.02575183" />
      <inertia
        ixx="0.00000205"
        ixy="0.00000013"
        ixz="0.00000055"
        iyy="0.00000636"
        iyz="-0.00000001"
        izz="0.00000573" />
    </inertial>
    <visual>
      <origin xyz="0 0 0" rpy="0 0 0" />
      <geometry>
        <mesh filename="package://sim_robot/urdf/meshes/LINK_F2_L2.STL" />
      </geometry>
      <material name="">
        <color rgba="0.7 0.7 0.7 1" />
      </material>
    </visual>
    <collision>
      <origin xyz="0 0 0" rpy="0 0 0" />
      <geometry>
        <mesh filename="package://sim_robot/urdf/meshes/LINK_F2_L2.STL" />
      </geometry>
    </collision>
  </link>
  <joint name="J_F2_L2" type="revolute">
    <origin xyz="0.04825 0 0" rpy="1.5708 0 0" />
    <parent link="LINK_F2_L1" />
    <child link="LINK_F2_L2" />
    <axis xyz="0 0 1" />
    <limit
      lower="-0.4363"
      upper="1.5708"
      effort="1.5"
      velocity="25" />
  </joint>

<!-- right hand -->
  <link name="LINK_HAND_BASE_R">
    <inertial>
      <origin xyz="0.048419 0.004068 0.000167" rpy="0 0 0" />
      <mass value="0.5804" />
      <inertia
        ixx="0.0004471"
        ixy="0.00002308"
        ixz="-0.00004840"
        iyy="0.00056348"
        iyz="0.00002031"
        izz="0.00074463" />
    </inertial>
    <visual>
      <origin xyz="0 0 0" rpy="0 0 0" />
      <geometry>
        <mesh filename="package://sim_robot/urdf/meshes/LINK_HAND_BASE_R.STL" />
      </geometry>
      <material name="">
        <color rgba="0.7 0.7 0.7 1" />
      </material>
    </visual>
    <collision>
      <origin xyz="0 0 0" rpy="0 0 0" />
      <geometry>
        <mesh filename="package://sim_robot/urdf/meshes/LINK_HAND_BASE_R.STL" />
      </geometry>
    </collision>
  </link>
  <joint name="J_HAND_BASE_R" type="fixed">
    <origin xyz="0.0555 0 0" rpy="-1.5708 0 0" />
    <parent link="LINK_WRIST_R1" />
    <child link="LINK_HAND_BASE_R" />
  </joint>
  <link name="LINK_F0_R0">
    <inertial>
      <origin xyz="-0.00003617 0.00000000 0.00084515" rpy="0 0 0" />
      <mass value="0.026087" />
      <inertia
        ixx="0.00000192"
        ixy="0"
        ixz="0"
        iyy="0.00000152"
        iyz="0"
        izz="0.00000122" />
    </inertial>
    <visual>
      <origin xyz="0 0 0" rpy="0 0 0" />
      <geometry>
        <mesh filename="package://sim_robot/urdf/meshes/LINK_F0_L0.STL" />
      </geometry>
      <material name="">
        <color rgba="0.7 0.7 0.7 1" />
      </material>
    </visual>
    <collision>
      <origin xyz="0 0 0" rpy="0 0 0" />
      <geometry>
        <mesh filename="package://sim_robot/urdf/meshes/LINK_F0_L0.STL" />
      </geometry>
    </collision>
  </link>
  <joint name="J_F0_R0" type="revolute">
    <origin xyz="0.021499 -0.0225 0.020865" rpy="1.5708 0 -1.5708" />
    <parent link="LINK_HAND_BASE_R" />
    <child link="LINK_F0_R0" />
    <axis xyz="0 0 1" />
    <limit
      lower="0"
      upper="1.9199"
      effort="3"
      velocity="25" />
  </joint>
  <link name="LINK_F0_R1">
    <inertial>
      <origin xyz="0.03750623 -0.00008894 -0.00016480" rpy="0 0 0" />
      <mass value="0.06888161" />
      <inertia
        ixx="0.00000650"
        ixy="-0.00000013"
        ixz="0.00000001"
        iyy="0.00002055"
        iyz="0.00000003"
        izz="0.00002001" />
    </inertial>
    <visual>
      <origin xyz="0 0 0" rpy="0 0 0" />
      <geometry>
        <mesh filename="package://sim_robot/urdf/meshes/LINK_F0_L1.STL" />
      </geometry>
      <material name="">
        <color rgba="0.7 0.7 0.7 1" />
      </material>
    </visual>
    <collision>
      <origin xyz="0 0 0" rpy="0 0 0" />
      <geometry>
        <mesh filename="package://sim_robot/urdf/meshes/LINK_F0_L1.STL" />
      </geometry>
    </collision>
  </link>
  <joint name="J_F0_R1" type="revolute">
    <origin xyz="0 0 0" rpy="-1.5708 0 0" />
    <parent link="LINK_F0_R0" />
    <child link="LINK_F0_R1" />
    <axis xyz="0 0 1" />
    <limit
      lower="-0.1745"
      upper="0.7854"
      effort="3"
      velocity="25" />
  </joint>
  <link name="LINK_F0_R2">
    <inertial>
      <origin xyz="0.02089747 -0.00213483 0.00106078" rpy="0 0 0" />
      <mass value="0.03102375" />
      <inertia
        ixx="0.00000240"
        ixy="-0.00000010"
        ixz="0.00000057"
        iyy="0.00000708"
        iyz="0.00000004"
        izz="0.00000642" />
    </inertial>
    <visual>
      <origin xyz="0 0 0" rpy="0 0 0" />
      <geometry>
        <mesh filename="package://sim_robot/urdf/meshes/LINK_F0_L2.STL" />
      </geometry>
      <material name="">
        <color rgba="0.7 0.7 0.7 1" />
      </material>
    </visual>
    <collision>
      <origin xyz="0 0 0" rpy="0 0 0" />
      <geometry>
        <mesh filename="package://sim_robot/urdf/meshes/LINK_F0_L2.STL" />
      </geometry>
    </collision>
  </link>
  <joint name="J_F0_R2" type="revolute">
    <origin xyz="0.05425 0 0" rpy="0 0 0" />
    <parent link="LINK_F0_R1" />
    <child link="LINK_F0_R2" />
    <axis xyz="0 0 1" />
    <limit
      lower="-0.4363"
      upper="1.5708"
      effort="1.5"
      velocity="25" />
  </joint>
  <link name="LINK_F1_R0">
    <inertial>
      <origin xyz="0.00003617 0 -0.00084515" rpy="0 0 0" />
      <mass value="0.026087" />
      <inertia
        ixx="0.00000192"
        ixy="0"
        ixz="0"
        iyy="0.00000152"
        iyz="0"
        izz="0.00000122" />
    </inertial>
    <visual>
      <origin xyz="0 0 0" rpy="0 0 0" />
      <geometry>
        <mesh filename="package://sim_robot/urdf/meshes/LINK_F1_L0.STL" />
      </geometry>
      <material name="">
        <color rgba="0.7 0.7 0.7 1" />
      </material>
    </visual>
    <collision>
      <origin xyz="0 0 0" rpy="0 0 0" />
      <geometry>
        <mesh filename="package://sim_robot/urdf/meshes/LINK_F1_L0.STL" />
      </geometry>
    </collision>
  </link>
  <joint name="J_F1_R0" type="revolute">
    <origin xyz="0.10232 -0.0225 0.00574" rpy="1.5708 0 0" />
    <parent link="LINK_HAND_BASE_R" />
    <child link="LINK_F1_R0" />
    <axis xyz="0 0 1" />
    <limit
      lower="-0.4363"
      upper="1.8326"
      effort="3"
      velocity="25" />
  </joint>
  <link name="LINK_F1_R1">
    <inertial>
      <origin xyz="0.03243751 -0.00016602 0.00016480" rpy="0 0 0" />
      <mass value="0.07027318" />
      <inertia
        ixx="0.00000696"
        ixy="0.00000002"
        ixz="0.00000005"
        iyy="0.00001858"
        iyz="-0.00000003"
        izz="0.00001779" />
    </inertial>
    <visual>
      <origin xyz="0 0 0" rpy="0 0 0" />
      <geometry>
        <mesh filename="package://sim_robot/urdf/meshes/LINK_F1_L1.STL" />
      </geometry>
      <material name="">
        <color rgba="0.7 0.7 0.7 1" />
      </material>
    </visual>
    <collision>
      <origin xyz="0 0 0" rpy="0 0 0" />
      <geometry>
        <mesh filename="package://sim_robot/urdf/meshes/LINK_F1_L1.STL" />
      </geometry>
    </collision>
  </link>
  <joint name="J_F1_R1" type="revolute">
    <origin xyz="0 0 0" rpy="1.5708 0 0" />
    <parent link="LINK_F1_R0" />
    <child link="LINK_F1_R1" />
    <axis xyz="0 0 1" />
    <limit
      lower="-0.4363"
      upper="0.4363"
      effort="3"
      velocity="25" />
  </joint>
  <link name="LINK_F1_R2">
    <inertial>
      <origin xyz="0.02080647 -0.00102362 0.00132199" rpy="0 0 0" />
      <mass value="0.02575183" />
      <inertia
        ixx="0.00000205"
        ixy="0.00000013"
        ixz="-0.00000055"
        iyy="0.00000636"
        iyz="0.00000001"
        izz="0.00000573" />
    </inertial>
    <visual>
      <origin xyz="0 0 0" rpy="0 0 0" />
      <geometry>
        <mesh filename="package://sim_robot/urdf/meshes/LINK_F1_L2.STL" />
      </geometry>
      <material name="">
        <color rgba="0.7 0.7 0.7 1" />
      </material>
    </visual>
    <collision>
      <origin xyz="0 0 0" rpy="0 0 0" />
      <geometry>
        <mesh filename="package://sim_robot/urdf/meshes/LINK_F1_L2.STL" />
      </geometry>
    </collision>
  </link>
  <joint name="J_F1_R2" type="revolute">
    <origin xyz="0.04825 0 0" rpy="-1.5708 0 0" />
    <parent link="LINK_F1_R1" />
    <child link="LINK_F1_R2" />
    <axis xyz="0 0 1" />
    <limit
      lower="-0.4363"
      upper="1.5708"
      effort="1.5"
      velocity="25" />
  </joint>
  <link name="LINK_F2_R0">
    <inertial>
      <origin xyz="0.00003617 0 -0.00084515" rpy="0 0 0" />
      <mass value="0.026087" />
      <inertia
        ixx="0.00000192"
        ixy="0"
        ixz="0"
        iyy="0.00000152"
        iyz="0"
        izz="0.00000122" />
    </inertial>
    <visual>
      <origin xyz="0 0 0" rpy="0 0 0" />
      <geometry>
        <mesh filename="package://sim_robot/urdf/meshes/LINK_F2_L0.STL" />
      </geometry>
      <material name="">
        <color rgba="0.7 0.7 0.7 1" />
      </material>
    </visual>
    <collision>
      <origin xyz="0 0 0" rpy="0 0 0" />
      <geometry>
        <mesh filename="package://sim_robot/urdf/meshes/LINK_F2_L0.STL" />
      </geometry>
    </collision>
  </link>
  <joint name="J_F2_R0" type="revolute">
    <origin xyz="0.10232 0.0225 0.00574" rpy="1.5708 0 0" />
    <parent link="LINK_HAND_BASE_R" />
    <child link="LINK_F2_R0" />
    <axis xyz="0 0 1" />
    <limit
      lower="-0.4363"
      upper="1.8326"
      effort="3"
      velocity="25" />
  </joint>
  <link name="LINK_F2_R1">
    <inertial>
      <origin xyz="0.03243751 -0.00016602 0.00016480" rpy="0 0 0" />
      <mass value="0.07027318" />
      <inertia
        ixx="0.00000696"
        ixy="0.00000002"
        ixz="0.00000005"
        iyy="0.00001858"
        iyz="-0.00000003"
        izz="0.00001779" />
    </inertial>
    <visual>
      <origin xyz="0 0 0" rpy="0 0 0" />
      <geometry>
        <mesh filename="package://sim_robot/urdf/meshes/LINK_F2_L1.STL" />
      </geometry>
      <material name="">
        <color rgba="0.7 0.7 0.7 1" />
      </material>
    </visual>
    <collision>
      <origin xyz="0 0 0" rpy="0 0 0" />
      <geometry>
        <mesh filename="package://sim_robot/urdf/meshes/LINK_F2_L1.STL" />
      </geometry>
    </collision>
  </link>
  <joint name="J_F2_R1" type="revolute">
    <origin xyz="0 0 0" rpy="1.5708 0 0" />
    <parent link="LINK_F2_R0" />
    <child link="LINK_F2_R1" />
    <axis xyz="0 0 1" />
    <limit
      lower="-0.4363"
      upper="0.4363"
      effort="3"
      velocity="25" />
  </joint>
  <link name="LINK_F2_R2">
    <inertial>
      <origin xyz="0.02080647 -0.00102362 0.00132199" rpy="0 0 0" />
      <mass value="0.02575183" />
      <inertia
        ixx="0.00000205"
        ixy="0.00000013"
        ixz="-0.00000055"
        iyy="0.00000636"
        iyz="0.00000001"
        izz="0.00000573" />
    </inertial>
    <visual>
      <origin xyz="0 0 0" rpy="0 0 0" />
      <geometry>
        <mesh filename="package://sim_robot/urdf/meshes/LINK_F2_L2.STL" />
      </geometry>
      <material name="">
        <color rgba="0.7 0.7 0.7 1" />
      </material>
    </visual>
    <collision>
      <origin xyz="0 0 0" rpy="0 0 0" />
      <geometry>
        <mesh filename="package://sim_robot/urdf/meshes/LINK_F2_L2.STL" />
      </geometry>
    </collision>
  </link>
  <joint name="J_F2_R2" type="revolute">
    <origin xyz="0.04825 0 0" rpy="-1.5708 0 0" />
    <parent link="LINK_F2_R1" />
    <child link="LINK_F2_R2" />
    <axis xyz="0 0 1" />
    <limit
      lower="-0.4363"
      upper="1.5708"
      effort="1.5"
      velocity="25" />
  </joint>
</robot>
