<mujoco model="MOBILE_XMAN_URDF_V1_2">
    <compiler angle="radian" coordinate="local" inertiafromgeom='auto' meshdir="../../../"/>
    <option timestep="0.005" apirate="100" iterations="20" noslip_iterations="20" tolerance="1e-10" impratio="10" gravity="0 0 -9.81" solver="PGS" cone="elliptic"/>
    <size njmax="10000" nconmax="10000" nstack="500000000"/>
    <visual>
        <map fogstart="3" fogend="5" force="0.1" znear="0.1"/>
        <quality shadowsize="4096" offsamples="8"/>
        <global offwidth="3024" offheight="1680"/>
    </visual>
    <default class="main">
        <joint limited="true" margin="0.0" armature="0.001" damping="0.05" frictionloss="0.000"/>
        <geom friction="1 0.5 0.1" margin="0.0" condim="4" solimp="0.95 0.99 0.01"/>
        <site size="0.005 0 0" rgba="0.4 0.9 0.4 1"/>
        <general ctrllimited="true" ctrlrange="-3.14 3.14"/>
        <default class="Arm">
            <joint margin="0.0005" armature="0.0" damping="25" stiffness="0" frictionloss="0.000" limited="true"/>
            <default class="Effector">
                <geom type="mesh" contype="1" conaffinity="0" condim="4" group="4"/>
                <joint margin="0.0" armature="0.01" damping="0.5" frictionloss="0.0" limited="true"/>
            </default>
        </default>
    </default>
    <actuator>
        <motor name="J_LAT_HIP" ctrllimited="true" ctrlrange="-0.6981 4.7124" joint="J_LAT_HIP" forcelimited="true" forcerange="-1000 1000"/>
        <!-- <motor name='J_LAT_LEG_L' joint='J_LAT_LEG_L' ctrllimited="true" ctrlrange="-1000 1000"/> -->
        <!-- <motor name='J_LAT_WHEEL_L' joint='J_LAT_WHEEL_L' ctrllimited="true" ctrlrange="-24 24"/> -->
        <!-- <motor name='J_LAT_FOOT_L' joint='J_LAT_FOOT_L' ctrllimited="true" ctrlrange="-61 61"/> -->
        <motor name="J_LAT_FOOT_L"  joint="J_LAT_FOOT_L"  forcelimited="true" forcerange="-61 61"     ctrllimited="true" ctrlrange="-1.4835 0.6981"  />
        <!-- <motor name='J_LAT_LEG_R' joint='J_LAT_LEG_R' ctrllimited="true" ctrlrange="-1000 1000"/> -->
        <!-- <motor name='J_LAT_WHEEL_R' joint='J_LAT_WHEEL_R' ctrllimited="true" ctrlrange="-24 24"/> -->
        <!-- <motor name='J_LAT_FOOT_R' joint='J_LAT_FOOT_R' ctrllimited="true" ctrlrange="-61 61"/> -->
        <motor name="J_LAT_FOOT_R"  joint="J_LAT_FOOT_R"  forcelimited="true" forcerange="-61 61"     ctrllimited="true" ctrlrange="-1.4835 0.6981"   />
        <motor name="J_MED_HIP" ctrllimited="true" ctrlrange="-1.5708 0.6981" joint="J_MED_HIP" forcelimited="true" forcerange="-1000 1000" />
        <!-- <motor name='J_MED_LEG_L' joint='J_MED_LEG_L' ctrllimited="true" ctrlrange="-1000 1000"/> -->
        <!-- <motor name='J_MED_WHEEL_L' joint='J_MED_WHEEL_L' ctrllimited="true" ctrlrange="-0.1 0.1"/> -->
        <!-- <motor name='J_MED_FOOT_L' joint='J_MED_FOOT_L' ctrllimited="true" ctrlrange="-61 61"/> -->
        <motor name="J_MED_FOOT_L"  joint="J_MED_FOOT_L"  forcelimited="true" forcerange="-61 61"     ctrllimited="true" ctrlrange="-1.4835 0.6981"  />
        <!-- <motor name='J_MED_LEG_R' joint='J_MED_LEG_R' ctrllimited="true" ctrlrange="-1000 1000"/> -->
        <!-- <motor name='J_MED_WHEEL_R' joint='J_MED_WHEEL_R' ctrllimited="true" ctrlrange="-0.1 0.1"/> -->
        <!-- <motor name='J_MED_FOOT_R' joint='J_MED_FOOT_R' ctrllimited="true" ctrlrange="-61 61"/> -->
        <motor name="J_MED_FOOT_R"  joint="J_MED_FOOT_R"  forcelimited="true" forcerange="-61 61"     ctrllimited="true" ctrlrange="-1.4835 0.6981" />

        <motor name="J_WAIST_PITCH" ctrllimited="true" ctrlrange="-0.6981 1.5708" joint="J_WAIST_PITCH" forcelimited="true" forcerange="-1000 1000" />
        <!-- <motor name='J_WAIST_YAW' ctrllimited="true"  ctrlrange="-1.3614 1.3614" joint='J_WAIST_YAW' forcelimited="true" forcerange="-1000 1000"/> -->
        <!-- <motor name='J_HEAD' ctrllimited="true"  ctrlrange="-0.6109 1.1345" joint='J_HEAD' forcelimited="true" forcerange="-1000 1000"/> -->

        <motor name='J_SHOULDER_L1' ctrllimited="true" ctrlrange="-3.6652 1.5708" joint='J_SHOULDER_L1' forcelimited="true" forcerange="-1000 1000"/>
        <motor name='J_SHOULDER_L2' ctrllimited="true" ctrlrange="-0.261799 2.2689" joint='J_SHOULDER_L2' forcelimited="true" forcerange="-1000 1000"/>
        <motor name='J_SHOULDER_L3' ctrllimited="true"  ctrlrange="-2.6180 2.6180" joint='J_SHOULDER_L3' forcelimited="true" forcerange="-1000 1000"/>
        <motor name='J_ELBOW_L1' ctrllimited="true" ctrlrange="-1.7453 0" joint='J_ELBOW_L1' forcelimited="true" forcerange="-1000 1000"/>
        <!-- <motor name='J_ELBOW_L2' ctrllimited="true" ctrlrange="-2.6180 2.6180" joint='J_ELBOW_L2' forcelimited="true" forcerange="-1000 1000"/>
        <motor name="J_WRIST_L1" ctrllimited="true" ctrlrange="-1.0472 1.0472" joint="J_WRIST_L1" kp="100" forcelimited="true" forcerange="-300 300"/>
        <motor name="J_WRIST_L2" ctrllimited="true" ctrlrange="-0.7854 0.7854" joint="J_WRIST_L2" kp="100" forcelimited="true" forcerange="-300 300"/>

        <motor name='J_F0_CMR_L' ctrllimited="true" kp="100" joint='J_F0_CMR_L' ctrlrange="0 1.5708" forcelimited="true" forcerange="-40 40" />
        <motor name='J_F0_CMP_L' ctrllimited="true" kp="100" joint='J_F0_CMP_L' ctrlrange="-0.349066 1.22117" forcelimited="true" forcerange="-40 40"/>
        <motor name='J_F0_MPP_L' ctrllimited="true" kp="100" ctrlrange="0 1.5708" joint='J_F0_MPP_L' forcelimited="true" forcerange="-40 40"/>
        <motor name='J_F0_IP_L' ctrllimited="true" kp="100" ctrlrange="0 1.7" joint='J_F0_IP_L' forcelimited="true" forcerange="-40 40"/>
        <motor name='J_F1_MPR_L' ctrllimited="true" kp="100" ctrlrange="-0.349066 0.349066" joint='J_F1_MPR_L' forcelimited="true" forcerange="-40 40"/>
        <motor name='J_F1_MPP_L' ctrllimited="true" kp="100" ctrlrange="0 1.5708" joint='J_F1_MPP_L' forcelimited="true" forcerange="-40 40"/>
        <motor name='J_F1_PIP_L' ctrllimited="true" kp="100" ctrlrange="0 1.5708" joint='J_F1_PIP_L' forcelimited="true" forcerange="-40 40"/>
        <motor name='J_F1_DIP_L' ctrllimited="true" kp="100" ctrlrange="0 1.7" joint='J_F1_DIP_L' forcelimited="true" forcerange="-40 40"/>
        <motor name='J_F2_MPR_L' ctrllimited="true" kp="100" joint='J_F2_MPR_L' ctrlrange="-0.349066 0.349066" forcelimited="true" forcerange="-40 40"/>
        <motor name='J_F2_MPP_L' ctrllimited="true" kp="100" joint='J_F2_MPP_L' ctrlrange="0 1.5708" forcelimited="true" forcerange="-40 40"/>
        <motor name='J_F2_PIP_L' ctrllimited="true" kp="100" ctrlrange="0 1.5708" joint='J_F2_PIP_L' forcelimited="true" forcerange="-40 40"/>
        <motor name='J_F2_DIP_L' ctrllimited="true" kp="100" ctrlrange="0 1.7" joint='J_F2_DIP_L' forcelimited="true" forcerange="-40 40"/>
        <motor name='J_F3_MPP_L' ctrllimited="true" kp="100" ctrlrange="0 1.5708" joint='J_F3_MPP_L' forcelimited="true" forcerange="-40 40"/>
        <motor name='J_F3_PIP_L' ctrllimited="true" kp="100" ctrlrange="0 1.5708" joint='J_F3_PIP_L' forcelimited="true" forcerange="-40 40"/>
        <motor name='J_F3_DIP_L' ctrllimited="true" kp="100" ctrlrange="0 1.7" joint='J_F3_DIP_L' forcelimited="true" forcerange="-40 40"/>
        <motor name='J_F4_MPP_L' ctrllimited="true" kp="100" ctrlrange="0 1.5708" joint='J_F4_MPP_L' forcelimited="true" forcerange="-40 40"/>
        <motor name='J_F4_PIP_L' ctrllimited="true" kp="100" ctrlrange="0 1.5708" joint='J_F4_PIP_L' forcelimited="true" forcerange="-40 40"/>
        <motor name='J_F4_DIP_L' ctrllimited="true" kp="100" ctrlrange="0 1.7" joint='J_F4_DIP_L' forcelimited="true" forcerange="-40 40"/> -->

        <motor name='J_SHOULDER_R1' ctrllimited="true"  ctrlrange="-3.6652 1.5708" joint='J_SHOULDER_R1' forcelimited="true" forcerange="-1000 1000" />
        <motor name='J_SHOULDER_R2' ctrllimited="true" ctrlrange="-2.2689 0.261799" joint='J_SHOULDER_R2' forcelimited="true" forcerange="-1000 1000" />
        <motor name='J_SHOULDER_R3' ctrllimited="true"  ctrlrange="-2.6180 2.6180" joint='J_SHOULDER_R3' forcelimited="true" forcerange="-1000 1000" />
        <motor name='J_ELBOW_R1' ctrllimited="true" ctrlrange="-1.7453 0" joint='J_ELBOW_R1' forcelimited="true" forcerange="-1000 1000" />
        <!-- <motor name='J_ELBOW_R2' ctrllimited="true" kp="1000" ctrlrange="-2.6180 2.6180" joint='J_ELBOW_R2' forcelimited="true" forcerange="-1000 1000"/>
        <motor name="J_WRIST_R1" ctrllimited="true" ctrlrange="-1.0472 1.0472" joint="J_WRIST_R1" kp="100" forcelimited="true" forcerange="-300 300"/>
        <motor name="J_WRIST_R2" ctrllimited="true" ctrlrange="-0.7854 0.7854" joint="J_WRIST_R2" kp="100" forcelimited="true" forcerange="-300 300"/>

        <motor name='J_F0_CMR_R' ctrllimited="true" kp="100" joint='J_F0_CMR_R' ctrlrange="0 1.5708" forcelimited="true" forcerange="-40 40" />
        <motor name='J_F0_CMP_R' ctrllimited="true" kp="100" joint='J_F0_CMP_R' ctrlrange="-0.349066 1.22117" forcelimited="true" forcerange="-40 40"/>
        <motor name='J_F0_MPP_R' ctrllimited="true" kp="100" ctrlrange="0 1.5708" joint='J_F0_MPP_R' forcelimited="true" forcerange="-40 40"/>
        <motor name='J_F0_IP_R' ctrllimited="true" kp="100" ctrlrange="0 1.7" joint='J_F0_IP_R' forcelimited="true" forcerange="-40 40"/>
        <motor name='J_F1_MPR_R' ctrllimited="true" kp="100" ctrlrange="-0.349066 0.349066" joint='J_F1_MPR_R' forcelimited="true" forcerange="-40 40"/>
        <motor name='J_F1_MPP_R' ctrllimited="true" kp="100" ctrlrange="0 1.5708" joint='J_F1_MPP_R' forcelimited="true" forcerange="-40 40"/>
        <motor name='J_F1_PIP_R' ctrllimited="true" kp="100" ctrlrange="0 1.5708" joint='J_F1_PIP_R' forcelimited="true" forcerange="-40 40"/>
        <motor name='J_F1_DIP_R' ctrllimited="true" kp="100" ctrlrange="0 1.7" joint='J_F1_DIP_R' forcelimited="true" forcerange="-40 40"/>
        <motor name='J_F2_MPR_R' ctrllimited="true" kp="100" joint='J_F2_MPR_R' ctrlrange="-0.349066 0.349066" forcelimited="true" forcerange="-40 40"/>
        <motor name='J_F2_MPP_R' ctrllimited="true" kp="100" joint='J_F2_MPP_R' ctrlrange="0 1.5708" forcelimited="true" forcerange="-40 40"/>
        <motor name='J_F2_PIP_R' ctrllimited="true" kp="100" ctrlrange="0 1.5708" joint='J_F2_PIP_R' forcelimited="true" forcerange="-40 40"/>
        <motor name='J_F2_DIP_R' ctrllimited="true" kp="100" ctrlrange="0 1.7" joint='J_F2_DIP_R' forcelimited="true" forcerange="-40 40"/>
        <motor name='J_F3_MPP_R' ctrllimited="true" kp="100" ctrlrange="0 1.5708" joint='J_F3_MPP_R' forcelimited="true" forcerange="-40 40"/>
        <motor name='J_F3_PIP_R' ctrllimited="true" kp="100" ctrlrange="0 1.5708" joint='J_F3_PIP_R' forcelimited="true" forcerange="-40 40"/>
        <motor name='J_F3_DIP_R' ctrllimited="true" kp="100" ctrlrange="0 1.7" joint='J_F3_DIP_R' forcelimited="true" forcerange="-40 40"/>
        <motor name='J_F4_MPP_R' ctrllimited="true" kp="100" ctrlrange="0 1.5708" joint='J_F4_MPP_R' forcelimited="true" forcerange="-40 40"/>
        <motor name='J_F4_PIP_R' ctrllimited="true" kp="100" ctrlrange="0 1.5708" joint='J_F4_PIP_R' forcelimited="true" forcerange="-40 40"/>
        <motor name='J_F4_DIP_R' ctrllimited="true" kp="100" ctrlrange="0 1.7" joint='J_F4_DIP_R' forcelimited="true" forcerange="-40 40"/> -->
    </actuator>
    <asset>
        <texture builtin="checker" height="512" name="texplane" rgb1=".2 .3 .4" rgb2=".1 0.15 0.2" type="2d" width="512"/>
        <material name="floorplane" reflectance="0.3" texrepeat="1 1" texture="texplane" texuniform="true"/>
        <mesh name="LINK_BASE" file="./platforms/xman/description/xman_v1.2/meshes/LINK_BASE.STL" />
        <mesh name="LINK_LAT_HIP" file="./platforms/xman/description/xman_v1.2/meshes/LINK_LAT_HIP.STL" />
        <mesh name="LINK_LAT_LEG_L" file="./platforms/xman/description/xman_v1.2/meshes/LINK_LAT_LEG_L.STL" />
        <mesh name="LINK_LAT_WHEEL_L" file="./platforms/xman/description/xman_v1.2/meshes/LINK_LAT_WHEEL_L.STL" />
        <mesh name="LINK_LAT_FOOT_L" file="./platforms/xman/description/xman_v1.2/meshes/LINK_LAT_FOOT_L.STL" />
        <mesh name="LINK_LAT_LEG_R" file="./platforms/xman/description/xman_v1.2/meshes/LINK_LAT_LEG_R.STL" />
        <mesh name="LINK_LAT_WHEEL_R" file="./platforms/xman/description/xman_v1.2/meshes/LINK_LAT_WHEEL_R.STL" />
        <mesh name="LINK_LAT_FOOT_R" file="./platforms/xman/description/xman_v1.2/meshes/LINK_LAT_FOOT_R.STL" />
        <mesh name="LINK_MED_HIP" file="./platforms/xman/description/xman_v1.2/meshes/LINK_MED_HIP.STL" />
        <mesh name="LINK_MED_LEG_L" file="./platforms/xman/description/xman_v1.2/meshes/LINK_MED_LEG_L.STL" />
        <mesh name="LINK_MED_WHEEL_L" file="./platforms/xman/description/xman_v1.2/meshes/LINK_MED_WHEEL_L.STL" />
        <mesh name="LINK_MED_FOOT_L" file="./platforms/xman/description/xman_v1.2/meshes/LINK_MED_FOOT_L.STL" />
        <mesh name="LINK_MED_LEG_R" file="./platforms/xman/description/xman_v1.2/meshes/LINK_MED_LEG_R.STL" />
        <mesh name="LINK_MED_WHEEL_R" file="./platforms/xman/description/xman_v1.2/meshes/LINK_MED_WHEEL_R.STL" />
        <mesh name="LINK_MED_FOOT_R" file="./platforms/xman/description/xman_v1.2/meshes/LINK_MED_FOOT_R.STL" />
        <mesh name="LINK_WAIST_PITCH" file="./platforms/xman/description/xman_v1.2/meshes/LINK_WAIST_PITCH.STL" />
        <mesh name="LINK_WAIST_YAW" file="./platforms/xman/description/xman_v1.2/meshes/LINK_WAIST_YAW.STL" />
        <!-- <mesh name="LINK_WAIST_YAW" file="platforms/xman/description/xman_v1.2/meshes/LINK_WAIST_YAW_new.STL" /> -->
        <mesh name="LINK_HEAD" file="./platforms/xman/description/xman_v1.2/meshes/LINK_HEAD.STL" />
        <!-- <mesh name="LINK_SHOULDER_L1" file="platforms/xman/description/xman_v1.2/meshes/LINK_SHOULDER_L1.STL" /> -->
        <mesh name="LINK_SHOULDER_L1" file="./platforms/xman/description/xman_v1.2/meshes/LINK_SHOULDER_L1_new.STL" />
        <mesh name="LINK_SHOULDER_L2" file="./platforms/xman/description/xman_v1.2/meshes/LINK_SHOULDER_L2.STL" />
        <!-- <mesh name="LINK_SHOULDER_L3" file="platforms/xman/description/xman_v1.2/meshes/LINK_SHOULDER_L3.STL" /> -->
        <mesh name="LINK_SHOULDER_L3" file="./platforms/xman/description/xman_v1.2/meshes/LINK_SHOULDER_L3_new.STL" />
        <mesh name="LINK_ELBOW_L1" file="./platforms/xman/description/xman_v1.2/meshes/LINK_ELBOW_L1.STL" />
        <!-- <mesh name="LINK_ELBOW_L2" file="platforms/xman/description/xman_v1.2/meshes/LINK_ELBOW_L2.STL" /> -->
        <mesh name="LINK_ELBOW_L2" file="./platforms/xman/description/xman_v1.2/meshes/LINK_ELBOW_L2_new.STL" />
        <mesh name="LINK_WRIST_L1" file="./drivers/manipulators/trx_arm_gen2/description/meshes/v2/LINK_WRIST_1.STL" />
        <mesh name="LINK_WRIST_L2" file="./drivers/manipulators/trx_arm_gen2/description/meshes/v2/LINK_WRIST_2.STL" />
        <mesh name="LINK_PALM_L" file="./drivers/hands/trx_hand5/description/meshes/v1/left/LINK_PALM.STL" />
        <mesh name="LINK_F0_CMR_L" file="./drivers/hands/trx_hand5/description/meshes/v1/LINK_F0_CMR.STL" />
        <mesh name="LINK_F0_CMP_L" file="./drivers/hands/trx_hand5/description/meshes/v1/LINK_F0_CMP.STL" />
        <mesh name="LINK_F0_MPP_L" file="./drivers/hands/trx_hand5/description/meshes/v1/LINK_F0_MPP.STL" />
        <mesh name="LINK_F0_IP_L" file="./drivers/hands/trx_hand5/description/meshes/v1/LINK_F0_IP.STL" />
        <mesh name="LINK_F1_MPR_L" file="./drivers/hands/trx_hand5/description/meshes/v1/LINK_F1_MPR.STL" />
        <mesh name="LINK_F1_MPP_L" file="./drivers/hands/trx_hand5/description/meshes/v1/LINK_F1_MPP.STL" />
        <mesh name="LINK_F1_PIP_L" file="./drivers/hands/trx_hand5/description/meshes/v1/LINK_F1_PIP.STL" />
        <mesh name="LINK_F1_DIP_L" file="./drivers/hands/trx_hand5/description/meshes/v1/LINK_F1_DIP.STL" />
        <mesh name="LINK_F2_MPR_L" file="./drivers/hands/trx_hand5/description/meshes/v1/LINK_F2_MPR.STL" />
        <mesh name="LINK_F2_MPP_L" file="./drivers/hands/trx_hand5/description/meshes/v1/LINK_F2_MPP.STL" />
        <mesh name="LINK_F2_PIP_L" file="./drivers/hands/trx_hand5/description/meshes/v1/LINK_F2_PIP.STL" />
        <mesh name="LINK_F2_DIP_L" file="./drivers/hands/trx_hand5/description/meshes/v1/LINK_F2_DIP.STL" />
        <mesh name="LINK_F3_MPR_L" file="./drivers/hands/trx_hand5/description/meshes/v1/LINK_F3_MPR.STL" />
        <mesh name="LINK_F3_MPP_L" file="./drivers/hands/trx_hand5/description/meshes/v1/LINK_F3_MPP.STL" />
        <mesh name="LINK_F3_PIP_L" file="./drivers/hands/trx_hand5/description/meshes/v1/LINK_F3_PIP.STL" />
        <mesh name="LINK_F3_DIP_L" file="./drivers/hands/trx_hand5/description/meshes/v1/LINK_F3_DIP.STL" />
        <mesh name="LINK_F4_MPR_L" file="./drivers/hands/trx_hand5/description/meshes/v1/LINK_F4_MPR.STL" />
        <mesh name="LINK_F4_MPP_L" file="./drivers/hands/trx_hand5/description/meshes/v1/LINK_F4_MPP.STL" />
        <mesh name="LINK_F4_PIP_L" file="./drivers/hands/trx_hand5/description/meshes/v1/LINK_F4_PIP.STL" />
        <mesh name="LINK_F4_DIP_L" file="./drivers/hands/trx_hand5/description/meshes/v1/LINK_F4_DIP.STL" />
        <!-- <mesh name="LINK_SHOULDER_R1" file="platforms/xman/description/xman_v1.2/meshes/LINK_SHOULDER_R1.STL" /> -->
        <mesh name="LINK_SHOULDER_R1" file="./platforms/xman/description/xman_v1.2/meshes/LINK_SHOULDER_R1_new.STL" />
        <mesh name="LINK_SHOULDER_R2" file="./platforms/xman/description/xman_v1.2/meshes/LINK_SHOULDER_R2.STL" />
        <!-- <mesh name="LINK_SHOULDER_R3" file="platforms/xman/description/xman_v1.2/meshes/LINK_SHOULDER_R3.STL" /> -->
        <mesh name="LINK_SHOULDER_R3" file="./platforms/xman/description/xman_v1.2/meshes/LINK_SHOULDER_R3_new.STL" />
        <mesh name="LINK_ELBOW_R1" file="./platforms/xman/description/xman_v1.2/meshes/LINK_ELBOW_R1.STL" />
        <!-- <mesh name="LINK_ELBOW_R2" file="platforms/xman/description/xman_v1.2/meshes/LINK_ELBOW_R2.STL" /> -->
        <mesh name="LINK_ELBOW_R2" file="./platforms/xman/description/xman_v1.2/meshes/LINK_ELBOW_R2_new.STL" />
        <mesh name="LINK_WRIST_R1" file="./drivers/manipulators/trx_arm_gen2/description/meshes/v2/LINK_WRIST_1.STL" />
        <mesh name="LINK_WRIST_R2" file="./drivers/manipulators/trx_arm_gen2/description/meshes/v2/LINK_WRIST_2.STL" />
        <mesh name="LINK_PALM_R" file="./drivers/hands/trx_hand5/description/meshes/v1/right/LINK_PALM.STL" />
        <mesh name="LINK_F0_CMR_R" file="./drivers/hands/trx_hand5/description/meshes/v1/LINK_F0_CMR.STL" />
        <mesh name="LINK_F0_CMP_R" file="./drivers/hands/trx_hand5/description/meshes/v1/LINK_F0_CMP.STL" />
        <mesh name="LINK_F0_MPP_R" file="./drivers/hands/trx_hand5/description/meshes/v1/LINK_F0_MPP.STL" />
        <mesh name="LINK_F0_IP_R" file="./drivers/hands/trx_hand5/description/meshes/v1/LINK_F0_IP.STL" />
        <mesh name="LINK_F1_MPR_R" file="./drivers/hands/trx_hand5/description/meshes/v1/LINK_F1_MPR.STL" />
        <mesh name="LINK_F1_MPP_R" file="./drivers/hands/trx_hand5/description/meshes/v1/LINK_F1_MPP.STL" />
        <mesh name="LINK_F1_PIP_R" file="./drivers/hands/trx_hand5/description/meshes/v1/LINK_F1_PIP.STL" />
        <mesh name="LINK_F1_DIP_R" file="./drivers/hands/trx_hand5/description/meshes/v1/LINK_F1_DIP.STL" />
        <mesh name="LINK_F2_MPR_R" file="./drivers/hands/trx_hand5/description/meshes/v1/LINK_F2_MPR.STL" />
        <mesh name="LINK_F2_MPP_R" file="./drivers/hands/trx_hand5/description/meshes/v1/LINK_F2_MPP.STL" />
        <mesh name="LINK_F2_PIP_R" file="./drivers/hands/trx_hand5/description/meshes/v1/LINK_F2_PIP.STL" />
        <mesh name="LINK_F2_DIP_R" file="./drivers/hands/trx_hand5/description/meshes/v1/LINK_F2_DIP.STL" />
        <mesh name="LINK_F3_MPR_R" file="./drivers/hands/trx_hand5/description/meshes/v1/LINK_F3_MPR.STL" />
        <mesh name="LINK_F3_MPP_R" file="./drivers/hands/trx_hand5/description/meshes/v1/LINK_F3_MPP.STL" />
        <mesh name="LINK_F3_PIP_R" file="./drivers/hands/trx_hand5/description/meshes/v1/LINK_F3_PIP.STL" />
        <mesh name="LINK_F3_DIP_R" file="./drivers/hands/trx_hand5/description/meshes/v1/LINK_F3_DIP.STL" />
        <mesh name="LINK_F4_MPR_R" file="./drivers/hands/trx_hand5/description/meshes/v1/LINK_F4_MPR.STL" />
        <mesh name="LINK_F4_MPP_R" file="./drivers/hands/trx_hand5/description/meshes/v1/LINK_F4_MPP.STL" />
        <mesh name="LINK_F4_PIP_R" file="./drivers/hands/trx_hand5/description/meshes/v1/LINK_F4_PIP.STL" />
        <mesh name="LINK_F4_DIP_R" file="./drivers/hands/trx_hand5/description/meshes/v1/LINK_F4_DIP.STL" />
    </asset>
    <!-- Relations between bodies are generated by the corresponding URDF file platforms/xman/description/xman_v1.2/urdf/xman_v1.2.urdf using /path/to/mujoco/bin/compile tool-->
    <worldbody>
        <geom name="floor" pos="0. 0. 0" size="10 10 .1" type="plane" condim="4" material="floorplane" contype="1" conaffinity="1"/>
        <light directional="true" diffuse='1.0 1.0 1.0' pos="0 0 3" dir="0 0 -1"/>
        <!-- Mocap body to simulate mobile base controlled by received command [x,y,z,yaw] -->
        <!-- Welds mocap body with target body so that its mounted IMU sensor can be simulated correctly. -->
        <body name='mobile_base_mocap' pos="0 0 0.56797" quat="1 0 0 0" mocap="true">
            <geom contype="0" conaffinity="0" group="1" type="box" pos="0 0 -0.56797" size="0.5 0.3 0.001" rgba="0 1 0 1" />
        </body>
        <body name="LINK_BASE" pos="0 0 0.56797" quat="1 0 0 0">
            <joint type="free" limited="false" armature="0.1" damping="50" />
            <inertial pos="-0.041119 -0.001534 0.085187" quat="0.3419 0.6068 0.6406 0.3233" mass="10.39128" diaginertia="0.051728 0.073935 0.094572"/>
            <geom type="mesh" contype="0" conaffinity="0" group="1" rgba="0.752941 0.752941 0.752941 1" mesh="LINK_BASE" />
            <body name="LINK_LAT_HIP" pos="0 0.2255 0" quat="0.499998 -0.5 0.5 0.500002">
                <inertial pos="0.15913 3.4e-05 -0.24165" quat="0.702825 -0.077009 -0.0767047 0.70301" mass="8.4942" diaginertia="0.59817 0.355752 0.252278" />
                <joint damping="25" stiffness="0" frictionloss="0.000" name="J_LAT_HIP" pos="0 0 0" axis="0 0 1" limited="true" range="-0.6981 4.7124" />
                <geom type="mesh" contype="0" conaffinity="0" group="1" rgba="0.752941 0.752941 0.752941 1" mesh="LINK_LAT_HIP" />
                <body name="LINK_LAT_LEG_L" pos="0.186 0 0" quat="0.707105 0 0.707108 0">
                    <inertial pos="0.004339 -4.5e-05 0.24834" quat="0.999983 -0.000127762 -0.0048489 -0.00312641" mass="2.782" diaginertia="0.119721 0.11887 0.00359507" />
                    <!-- <joint name="J_LAT_LEG_L" pos="0 0 0" axis="0 0 1" type="slide" limited="true" range="0 0.32" /> -->
                    <geom type="mesh" contype="0" conaffinity="0" group="1" rgba="0.752941 0.752941 0.752941 1" mesh="LINK_LAT_LEG_L" />
                    <body name="LINK_LAT_WHEEL_L" pos="0 0 0.451" quat="0.707105 0 -0.707108 0">
                        <inertial pos="0 0 0.004702" quat="0.5 0.5 -0.5 0.5" mass="0.71345" diaginertia="0.002725 0.001602 0.001602" />
                        <!-- <joint name="J_LAT_WHEEL_L" pos="0 0 0" axis="0 0 1" limited="true" range="-1000000 1000000" /> -->
                        <geom name="GEOM_LAT_WHEEL_L" type="mesh" contype="0" conaffinity="1" group="1" rgba="0.752941 0.752941 0.752941 1" mesh="LINK_LAT_WHEEL_L" />
                    </body>
                    <body name="LINK_LAT_FOOT_L" pos="0 0 0.451" quat="0.707105 0 -0.707108 0">
                        <inertial pos="0 0 0" quat="0.5 0.5 -0.5 0.5" mass="0.5" diaginertia="0.003694 0.002053 0.002053" />
                        <joint name="J_LAT_FOOT_L" pos="0 0 0" axis="0 0 1" limited="true" range="-1.4835 0.6981" />
                        <geom type="mesh" contype="0" conaffinity="0" group="1" rgba="0.7529 0.7529 0.7529 1" mesh="LINK_LAT_FOOT_L" />
                    </body>
                </body>
                <body name="LINK_LAT_LEG_R" pos="0.186 0 -0.451" quat="0.707105 0 0.707108 0">
                    <inertial pos="-0.004339 4.5e-05 0.24834" quat="0.999983 0.000127762 0.0048489 -0.00312641" mass="2.782" diaginertia="0.119721 0.11887 0.00359507" />
                    <!-- <joint name="J_LAT_LEG_R" pos="0 0 0" axis="0 0 1" type="slide" limited="true" range="0 0.32" /> -->
                    <geom type="mesh" contype="0" conaffinity="0" group="1" rgba="0.752941 0.752941 0.752941 1" mesh="LINK_LAT_LEG_R" />
                    <body name="LINK_LAT_WHEEL_R" pos="0 0 0.451" quat="0.707105 0 -0.707108 0">
                        <inertial pos="0 0 -0.004702" quat="0.5 0.5 -0.5 0.5" mass="0.71345" diaginertia="0.002725 0.001602 0.001602" />
                        <!-- <joint name="J_LAT_WHEEL_R" pos="0 0 0" axis="0 0 1" limited="true" range="-1000000 1000000" /> -->
                        <geom name="GEOM_LAT_WHEEL_R" type="mesh" contype="0" conaffinity="1" group="1" rgba="0.752941 0.752941 0.752941 1" mesh="LINK_LAT_WHEEL_R" />
                    </body>
                    <body name="LINK_LAT_FOOT_R" pos="0 0 0.451" quat="0.707105 0 -0.707108 0">
                        <inertial pos="0 0 0" quat="0.5 0.5 -0.5 0.5" mass="0.5" diaginertia="0.003694 0.002053 0.002053" />
                        <joint name="J_LAT_FOOT_R" pos="0 0 0" axis="0 0 1" limited="true" range="-1.4835 0.6981" />
                        <geom type="mesh" contype="0" conaffinity="0" group="1" rgba="0.7529 0.7529 0.7529 1" mesh="LINK_LAT_FOOT_R" />
                    </body>
                </body>
            </body>
            <body name="LINK_MED_HIP" pos="0 0.12325 0" quat="0.499998 -0.5 0.5 0.500002">
                <inertial pos="0.17865 1.6e-05 -0.1091" quat="0.540328 0.455948 0.456611 0.540058" mass="8.3414" diaginertia="0.32349 0.228651 0.105269" />
                <joint damping="25" stiffness="0" frictionloss="0.000" name="J_MED_HIP" pos="0 0 0" axis="0 0 1" limited="true" range="-1.5708 0.6981" />
                <geom type="mesh" contype="0" conaffinity="0" group="1" rgba="0.752941 0.752941 0.752941 1" mesh="LINK_MED_HIP" />
                <body name="LINK_MED_LEG_L" pos="0.186 0 0" quat="0.707105 0 0.707108 0">
                    <inertial pos="0.004339 -4.5e-05 0.24834" quat="0.999983 -0.000127762 -0.0048489 -0.00312641" mass="2.782" diaginertia="0.119721 0.11887 0.00359507" />
                    <!-- <joint name="J_MED_LEG_L" pos="0 0 0" axis="0 0 1" type="slide" limited="true" range="0 0.32" /> -->
                    <geom type="mesh" contype="0" conaffinity="0" group="1" rgba="0.752941 0.752941 0.752941 1" mesh="LINK_MED_LEG_L" />
                    <body name="LINK_MED_WHEEL_L" pos="0 0 0.451" quat="0.707105 0 -0.707108 0">
                        <inertial pos="0 0 0.004702" quat="0.5 0.5 -0.5 0.5" mass="0.71345" diaginertia="0.002725 0.001602 0.001602" />
                        <!-- <joint name="J_MED_WHEEL_L" pos="0 0 0" axis="0 0 1" limited="true" range="-1000000 1000000" /> -->
                        <geom name="GEOM_MED_WHEEL_L" type="mesh" contype="0" conaffinity="1" group="1" rgba="0.752941 0.752941 0.752941 1" mesh="LINK_MED_WHEEL_L" />
                    </body>
                    <body name="LINK_MED_FOOT_L" pos="0 0 0.451" quat="0.707105 0 -0.707108 0">
                        <inertial pos="0 0 0" quat="0.5 0.5 -0.5 0.5" mass="0.5" diaginertia="0.003694 0.002053 0.002053" />
                        <joint name="J_MED_FOOT_L" pos="0 0 0" axis="0 0 1" limited="true" range="-1.4835 0.6981" />
                        <geom type="mesh" contype="0" conaffinity="0" group="1" rgba="0.7529 0.7529 0.7529 1" mesh="LINK_MED_FOOT_L" />
                    </body>
                </body>
                <body name="LINK_MED_LEG_R" pos="0.186 0 -0.2465" quat="0.707105 0 0.707108 0">
                    <inertial pos="-0.005339 4.5e-05 0.24834" quat="0.999983 0.000127762 0.0048489 -0.00312641" mass="2.782" diaginertia="0.119721 0.11887 0.00359507" />
                    <!-- <joint name="J_MED_LEG_R" pos="0 0 0" axis="0 0 1" type="slide" limited="true" range="0 0.32" /> -->
                    <geom type="mesh" contype="0" conaffinity="0" group="1" rgba="0.752941 0.752941 0.752941 1" mesh="LINK_MED_LEG_R" />
                    <body name="LINK_MED_WHEEL_R" pos="0 0 0.451" quat="0.707105 0 -0.707108 0">
                        <inertial pos="0 0 -0.003702" quat="0.5 0.5 -0.5 0.5" mass="0.71345" diaginertia="0.002725 0.001602 0.001602" />
                        <!-- <joint name="J_MED_WHEEL_R" pos="0 0 0" axis="0 0 1" limited="true" range="-1000000 1000000" /> -->
                        <geom name="GEOM_MED_WHEEL_R" type="mesh" contype="0" conaffinity="1" group="1" rgba="0.752941 0.752941 0.752941 1" mesh="LINK_MED_WHEEL_R" />
                    </body>
                    <body name="LINK_MED_FOOT_R" pos="0 0 0.451" quat="0.707105 0 -0.707108 0">
                        <inertial pos="0 0 0" quat="0.5 0.5 -0.5 0.5" mass="0.5" diaginertia="0.003694 0.002053 0.002053" />
                        <joint name="J_MED_FOOT_R" pos="0 0 0" axis="0 0 1" limited="true" range="-1.4835 0.6981" />
                        <geom type="mesh" contype="0" conaffinity="0" group="1" rgba="0.7529 0.7529 0.7529 1" mesh="LINK_MED_FOOT_R" />
                    </body>
                </body>
            </body>
            <body name="LINK_WAIST_PITCH" pos="0 0 0.15" quat="0.499998 -0.5 -0.5 -0.500002">
                <inertial pos="0.0690926 2.01797e-06 0.000461243" quat="0.680126 0.000628288 0.00220574 0.733092" mass="0.895764" diaginertia="0.00487164 0.00465432 0.00140778" />
                <joint damping="50" stiffness="0" name="J_WAIST_PITCH" pos="0 0 0" axis="0 0 1" limited="true" range="-0.6981 1.5708" />
                <geom type="mesh" contype="0" conaffinity="0" group="1" rgba="0.752941 0.752941 0.752941 1" mesh="LINK_WAIST_PITCH" />
                <body name="LINK_WAIST_YAW" pos="0.11 0 0" quat="0.499998 0.5 0.500002 0.5">
                    <!-- Fixed joint -->
                    <body name="LINK_IMU" pos="0.0468 0.0077 0.22576" quat="1 0 0 0">
                        <geom type="box" rgba="0 0 1 1" size="0.01 0.01 0.01" contype="0" conaffinity="0"/>
                        <site name="imu_site"/>
                    </body>
                    <inertial pos="-0.032476 -0.000483 0.18782" quat="0.996778 0.0014377 -0.0800972 -0.00411271" mass="15.4965" diaginertia="0.404612 0.352857 0.14191" />
                    <!-- <joint damping="25" name="J_WAIST_YAW" pos="0 0 0" axis="0 0 1" limited="true" range="-1.3614 1.3614" /> -->
                    <geom type="mesh" contype="0" conaffinity="0" group="1" rgba="0.752941 0.752941 0.752941 1" mesh="LINK_WAIST_YAW" />
                    <body name="LINK_HEAD" pos="0 0 0.448" quat="0.499998 -0.5 -0.5 -0.500002">
                        <inertial pos="0.021339 0.001489 0.002676" quat="0.540724 0.492911 0.466732 0.496807" mass="1.7813" diaginertia="0.00605473 0.00484264 0.00371762" />
                        <!-- <joint damping="25" stiffness="0" name="J_HEAD" pos="0 0 0" axis="0 0 1" limited="true" range="-0.6109 1.1345" /> -->
                        <site name="H_SITE" pos="0 0 0" size="0.02" rgba="0 1 0 1"/>
                        <geom type="mesh" contype="0" conaffinity="0" group="1" rgba="0.752941 0.752941 0.752941 1" mesh="LINK_HEAD" />
                    </body>
                    <!-- <body childclass="Arm" name="LINK_SHOULDER_L1" pos="0 0.16 0.4" quat="0.499998 -0.5 0.5 0.500002"> -->
                    <body childclass="Arm" name="LINK_SHOULDER_L1" pos="0 0.18 0.4" quat="0.499998 -0.5 0.5 0.500002">
                        <inertial pos="2e-05 0.002185 0.063744" quat="0.707059 0.00821607 -0.00821607 0.707059" mass="1.6989" diaginertia="0.00312856 0.002257 0.00209544" />
                        <joint name="J_SHOULDER_L1" pos="0 0 0" axis="0 0 1" limited="true" range="-3.6652 1.5708" />
                        <geom type="mesh" group="1" rgba="0.752941 0.752941 0.752941 1" mesh="LINK_SHOULDER_L1" />
                        <!-- <body name="LINK_SHOULDER_L2" pos="0 0 0.07" quat="0.707105 0.707108 0 0"> -->
                        <body name="LINK_SHOULDER_L2" pos="0 0 0.0465" quat="0.707105 0.707108 0 0">
                            <inertial pos="0.10988 0.000196 0.001131" quat="0.510873 0.483195 0.47866 0.525753" mass="1.8095" diaginertia="0.00373127 0.00355104 0.00156769" />
                            <joint name="J_SHOULDER_L2" pos="0 0 0" axis="0 0 1" limited="true" range="-0.261799 2.2689" />
                            <geom type="mesh" group="1" rgba="0.752941 0.752941 0.752941 1" mesh="LINK_SHOULDER_L2" />
                            <body name="LINK_SHOULDER_L3" pos="0.1685 0 0" quat="0.707105 0 0.707108 0">
                                <inertial pos="-0.000217 1.9e-05 0.060051" quat="0.713652 0.00131979 0.00216755 0.700496" mass="1.7403" diaginertia="0.00229102 0.002237 0.00142798" />
                                <joint name="J_SHOULDER_L3" pos="0 0 0" axis="0 0 1" limited="true" range="-2.6180 2.6180" />
                                <geom quat="0.707105 0 0 0.707108" type="mesh" group="1" rgba="0.752941 0.752941 0.752941 1" mesh="LINK_SHOULDER_L3" />
                                <body name="LINK_ELBOW_L1" pos="0 0 0.1425" quat="0.499998 -0.5 -0.5 -0.500002">
                                    <inertial pos="0.070289 0.000162 0.000289" quat="0.483424 0.510848 0.500864 0.504451" mass="1.4588" diaginertia="0.00254623 0.00249371 0.00114006" />
                                    <joint name="J_ELBOW_L1" pos="0 0 0" axis="0 0 1" limited="true" range="-1.7453 0" />
                                    <site name="E_L_SITE" pos="0 0 0" size="0.002" rgba="1 1 0 1"/>
                                    <geom quat="-3.67321e-06 1 0 0" type="mesh" group="1" rgba="0.752941 0.752941 0.752941 1" mesh="LINK_ELBOW_L1" />
                                    <body name="LINK_ELBOW_L2" pos="0.124 0 0" quat="0.499998 0.5 0.500002 0.5">
                                        <inertial pos="-0.000365 0.00147 0.101648" quat="0.736133 0.00323688 -0.00305844 0.676823" mass="1.37062" diaginertia="0.00696362 0.00636479 0.00179459" />
                                        <!-- <joint name="J_ELBOW_L2" pos="0 0 0" axis="0 0 1" limited="true" range="-2.6180 2.6180" /> -->
                                        <geom type="mesh" group="1" rgba="0.752941 0.752941 0.752941 1" mesh="LINK_ELBOW_L2" />
                                        <body name="LINK_WRIST_L1" pos="0 0 0.1885" quat="0.707105 0 -0.707108 0">
                                            <inertial pos="4e-06 -0.001549 0.001352" mass="0.021797" diaginertia="1.2e-05 7e-06 6e-06" />
                                            <!-- <joint name="J_WRIST_L1" pos="0 0 0" axis="0 0 1" limited="true" range="-1.0472 1.0472" /> -->
                                            <geom type="mesh" rgba="0.752941 0.752941 0.752941 1" mesh="LINK_WRIST_L1" />
                                            <body name="LINK_WRIST_L2" pos="0 0 0" quat="0.707105 -0.707108 0 0">
                                                <inertial pos="0.108985 6e-05 0.005756" quat="0.493883 0.481793 0.507907 0.515738" mass="1.32955" diaginertia="0.00587773 0.00455711 0.00166116" />
                                                <site name="W_L_SITE" pos="0 0 0" size="0.002" rgba="0 1 0 1"/>
                                                <!-- <joint name="J_WRIST_L2" pos="0 0 0" axis="0 0 1" limited="true" range="-0.7854 0.7854" /> -->
                                                <geom quat="0.707105 0.707108 0 0" type="mesh" contype="0" conaffinity="0" group="1" rgba="0.752941 0.752941 0.752941 1" mesh="LINK_WRIST_L2" />
                                                <body name="LINK_PALM_L" pos="0.039 -0.0065 0.0027" euler="0 3.1416 3.1416">
                                                    <site name="LINK_PALM_L"/>
                                                    <site name="LINK_PALM_LIDAR_L0" type="box" size="0.002 0.002 0.002" rgba="0 0 1 1" pos="0.056394 -0.0024896 0.0201" />
                                                    <site name="LINK_PALM_PROXIMITY_L0" type="cylinder" size="0.00152 0.0005" rgba="0 1 1 1" pos="0.0598016 -0.0022702 0.0201"/>
                                                    <geom type="mesh" contype="0" conaffinity="0" group="1" rgba="0.752941 0.752941 0.752941 1" pos="0.094391 -0.02376 0" quat="0.999848 0 0 -0.0174526" mesh="LINK_F3_MPR_L" />
                                                    <geom type="mesh" contype="0" conaffinity="0" group="1" rgba="0.752941 0.752941 0.752941 1" pos="0.085272 -0.045516 0" quat="0.999391 0 0 -0.0348994" mesh="LINK_F4_MPR_L" />
                                                    <geom contype="1" group="1" condim="4" rgba="0.752941 0.752941 0.752941 1" conaffinity="0" name="LINK_PALM_L" type="mesh" mesh="LINK_PALM_L"/>
                                                    <body name="LINK_F0_CMR_L" pos="0.038644 0.020454 0.0092393" quat="0.65328 0.653282 0.270599 0.270598">
                                                        <inertial pos="0.00283749 -0.000223308 -0.00103973" quat="0.477734 0.519348 0.522246 0.478861" mass="0.00559568" diaginertia="4.03214e-07 3.22464e-07 2.85515e-07" />
                                                        <!-- <joint name="J_F0_CMR_L" pos="0 0 0" axis="0 0 1" limited="true" range="0 1.5708" /> -->
                                                        <geom contype="1" conaffinity="1" group="1" condim="4" rgba="0.752941 0.752941 0.752941 1" name="LINK_F0_CMR_L" type="mesh" mesh="LINK_F0_CMR_L" />
                                                        <body name="LINK_F0_CMP_L" pos="0.01 0 0" quat="0.707105 0.707108 0 0">
                                                            <inertial pos="0.0178949 -0.00174704 1.51001e-05" quat="0.494457 0.490367 0.50584 0.509095" mass="0.0186139" diaginertia="4.39046e-06 4.15077e-06 1.68756e-06" />
                                                            <!-- <joint name="J_F0_CMP_L" pos="0 0 0" axis="0 0 1" limited="true" range="-0.349066 1.22117" /> -->
                                                            <geom contype="1" group="1" condim="4" rgba="0.752941 0.752941 0.752941 1" conaffinity="0" name="LINK_F0_CMP_L" type="mesh" mesh="LINK_F0_CMP_L" />
                                                            <body name="LINK_F0_MPP_L" pos="0.045 0 0">
                                                                <inertial pos="0.0134858 -0.00194755 3.70272e-05" quat="0.475399 0.537291 0.508262 0.476428" mass="0.0068671" diaginertia="7.44252e-07 6.07436e-07 3.89101e-07" />
                                                                <!-- <joint name="J_F0_MPP_L" pos="0 0 0" axis="0 0 1" limited="true" range="0 1.5708" /> -->
                                                                <geom contype="1" conaffinity="1" group="1" condim="4" rgba="0.752941 0.752941 0.752941 1" name="LINK_F0_MPP_L" type="mesh" mesh="LINK_F0_MPP_L" />
                                                                <body name="LINK_F0_IP_L" pos="0.027 0 0">
                                                                    <inertial pos="0.0125007 -0.00223535 -0.00038541" quat="0.507073 0.469661 0.4922 0.529183" mass="0.00512358" diaginertia="5.87347e-07 3.93558e-07 3.08372e-07" />
                                                                    <!-- <joint name="J_F0_IP_L" pos="0 0 0" axis="0 0 1" limited="true" range="0 1.7" /> -->
                                                                    <geom type="mesh" contype="0" conaffinity="0" group="1" rgba="0.752941 0.752941 0.752941 1" mesh="LINK_F0_IP_L" />
                                                                </body>
                                                            </body>
                                                        </body>
                                                    </body>
                                                    <body name="LINK_F1_MPR_L" pos="0.094 0.0245 0">
                                                        <inertial pos="0.00325879 -0.000161013 -0.00112841" quat="0.489597 0.490711 0.512578 0.506716" mass="0.00500155" diaginertia="3.46608e-07 2.56011e-07 2.3013e-07" />
                                                        <!-- <joint name="J_F1_MPR_L" pos="0 0 0" axis="0 0 1" limited="true" range="-0.349066 0.349066" /> -->
                                                        <geom contype="1" conaffinity="1" group="1" condim="4" rgba="0.752941 0.752941 0.752941 1" name="LINK_F1_MPR_L" type="mesh" mesh="LINK_F1_MPR_L" />
                                                        <body name="LINK_F1_MPP_L" pos="0.01 0 0" quat="0.707105 0.707108 0 0">
                                                            <inertial pos="0.0170176 -0.0010274 -3.54625e-05" quat="0.00293599 0.701784 0.00182744 0.712381" mass="0.0105685" diaginertia="1.98527e-06 1.88784e-06 4.99044e-07" />
                                                            <!-- <joint name="J_F1_MPP_L" pos="0 0 0" axis="0 0 1" limited="true" range="0 1.5708" /> -->
                                                            <geom contype="1" group="1" condim="4" rgba="0.752941 0.752941 0.752941 1" conaffinity="0" name="LINK_F1_MPP_L" type="mesh" mesh="LINK_F1_MPP_L" />
                                                            <body name="LINK_F1_PIP_L" pos="0.04 0 0">
                                                                <inertial pos="0.0135605 -0.00133924 4.55527e-05" quat="0.24806 0.693037 0.233958 0.635161" mass="0.00541254" diaginertia="4.91119e-07 4.82284e-07 1.96332e-07" />
                                                                <!-- <joint name="J_F1_PIP_L" pos="0 0 0" axis="0 0 1" limited="true" range="0 1.5708" /> -->
                                                                <geom contype="1" conaffinity="1" group="1" condim="4" rgba="0.752941 0.752941 0.752941 1" name="LINK_F1_PIP_L" type="mesh" mesh="LINK_F1_PIP_L" />
                                                                <body name="LINK_F1_DIP_L" pos="0.027 0 0">
                                                                    <inertial pos="0.0145494 -0.000408056 -0.000377853" quat="0.503609 0.47665 0.497905 0.520839" mass="0.00490823" diaginertia="4.18002e-07 3.17272e-07 1.97971e-07" />
                                                                    <!-- <joint name="J_F1_DIP_L" pos="0 0 0" axis="0 0 1" limited="true" range="0 1.7" /> -->
                                                                    <geom type="mesh" contype="0" conaffinity="0" group="1" rgba="0.752941 0.752941 0.752941 1" mesh="LINK_F1_DIP_L" />
                                                                </body>
                                                            </body>
                                                        </body>
                                                    </body>
                                                    <body name="LINK_F2_MPR_L" pos="0.1 0 0">
                                                        <inertial pos="0.00325879 -0.000161013 -0.00112841" quat="0.489597 0.490711 0.512578 0.506716" mass="0.00500155" diaginertia="3.46608e-07 2.56011e-07 2.3013e-07" />
                                                        <!-- <joint name="J_F2_MPR_L" pos="0 0 0" axis="0 0 1" limited="true" range="-0.349066 0.349066" /> -->
                                                        <geom contype="1" conaffinity="1" group="1" condim="4" rgba="0.752941 0.752941 0.752941 1" name="LINK_F2_MPR_L" type="mesh" mesh="LINK_F2_MPR_L" />
                                                        <body name="LINK_F2_MPP_L" pos="0.01 0 0" quat="0.707105 0.707108 0 0">
                                                            <inertial pos="0.0170176 -0.0010274 -3.54625e-05" quat="0.00293599 0.701784 0.00182744 0.712381" mass="0.0105685" diaginertia="1.98527e-06 1.88784e-06 4.99044e-07" />
                                                            <!-- <joint name="J_F2_MPP_L" pos="0 0 0" axis="0 0 1" limited="true" range="0 1.5708" /> -->
                                                            <geom contype="1" group="1" condim="4" rgba="0.752941 0.752941 0.752941 1" conaffinity="0" name="LINK_F2_MPP_L" type="mesh" mesh="LINK_F2_MPP_L" />
                                                            <body name="LINK_F2_PIP_L" pos="0.04 0 0">
                                                                <inertial pos="0.0135605 -0.00133924 4.55527e-05" quat="0.24806 0.693037 0.233958 0.635161" mass="0.00541254" diaginertia="4.91119e-07 4.82284e-07 1.96332e-07" />
                                                                <!-- <joint name="J_F2_PIP_L" pos="0 0 0" axis="0 0 1" limited="true" range="0 1.5708" /> -->
                                                                <geom contype="1" conaffinity="1" group="1" condim="4" rgba="0.752941 0.752941 0.752941 1" name="LINK_F2_PIP_L" type="mesh" mesh="LINK_F2_PIP_L" />
                                                                <body name="LINK_F2_DIP_L" pos="0.027 0 0">
                                                                    <inertial pos="0.0145494 -0.000408056 -0.000377853" quat="0.503609 0.47665 0.497905 0.520839" mass="0.00490823" diaginertia="4.18002e-07 3.17272e-07 1.97971e-07" />
                                                                    <!-- <joint name="J_F2_DIP_L" pos="0 0 0" axis="0 0 1" limited="true" range="0 1.7" /> -->
                                                                    <geom type="mesh" contype="0" conaffinity="0" group="1" rgba="0.752941 0.752941 0.752941 1" mesh="LINK_F2_DIP_L" />
                                                                </body>
                                                            </body>
                                                        </body>
                                                    </body>
                                                    <body name="LINK_F3_MPP_L" pos="0.104385 -0.024109 0" quat="0.706816 0.707094 -0.004447 -0.0202332">
                                                        <inertial pos="0.0183676 -0.00112703 2.96496e-05" quat="0.00403327 0.710887 0.00438157 0.703281" mass="0.00947234" diaginertia="1.97211e-06 1.89237e-06 4.63124e-07" />
                                                        <!-- <joint name="J_F3_MPP_L" pos="0 0 0" axis="0 0 1" limited="true" range="0 1.5708" /> -->
                                                        <geom contype="1" conaffinity="1" group="1" condim="4" rgba="0.752941 0.752941 0.752941 1" name="LINK_F3_MPP_L" type="mesh" mesh="LINK_F3_MPP_L" />
                                                        <body name="LINK_F3_PIP_L" pos="0.04 0 0" quat="0.999938 0 0 0.0111643">
                                                            <inertial pos="0.0120056 -0.00124466 8.56608e-05" quat="0.239898 0.661047 0.239175 0.669523" mass="0.00492442" diaginertia="5.05359e-07 5.0045e-07 1.96299e-07" />
                                                            <!-- <joint name="J_F3_PIP_L" pos="0 0 0" axis="0 0 1" limited="true" range="0 1.5708" /> -->
                                                            <geom contype="1" conaffinity="1" group="1" condim="4" rgba="0.752941 0.752941 0.752941 1" name="LINK_F3_PIP_L" type="mesh" mesh="LINK_F3_PIP_L" />
                                                            <body name="LINK_F3_DIP_L" pos="0.027 0 0">
                                                                <inertial pos="0.0138131 -0.000331974 5.37445e-05" quat="0.493521 0.494162 0.502438 0.509703" mass="0.00525721" diaginertia="4.32834e-07 3.30838e-07 2.09133e-07" />
                                                                <!-- <joint name="J_F3_DIP_L" pos="0 0 0" axis="0 0 1" limited="true" range="0 1.7" /> -->
                                                                <geom type="mesh" contype="0" conaffinity="0" group="1" rgba="0.752941 0.752941 0.752941 1" mesh="LINK_F3_DIP_L" />
                                                            </body>
                                                        </body>
                                                    </body>
                                                    <body name="LINK_F4_MPP_L" pos="0.0952476 -0.0462136 0" quat="0.706675 0.706677 -0.0246777 -0.0246776">
                                                        <inertial pos="0.0183676 -0.00112703 2.96567e-05" quat="0.00403081 0.710887 0.00437912 0.703281" mass="0.00947234" diaginertia="1.97212e-06 1.89237e-06 4.63127e-07" />
                                                        <!-- <joint name="J_F4_MPP_L" pos="0 0 0" axis="0 0 1" limited="true" range="0 1.5708" /> -->
                                                        <geom contype="1" conaffinity="1" group="1" condim="4" rgba="0.752941 0.752941 0.752941 1" name="LINK_F4_MPP_L" type="mesh" mesh="LINK_F4_MPP_L" />
                                                        <body name="LINK_F4_PIP_L" pos="0.04 0 0">
                                                            <inertial pos="0.0120056 -0.00124466 8.56605e-05" quat="0.239897 0.661047 0.239175 0.669523" mass="0.00492441" diaginertia="5.05359e-07 5.0045e-07 1.96299e-07" />
                                                            <!-- <joint name="J_F4_PIP_L" pos="0 0 0" axis="0 0 1" limited="true" range="0 1.5708" /> -->
                                                            <geom contype="1" conaffinity="1" group="1" condim="4" rgba="0.752941 0.752941 0.752941 1" name="LINK_F4_PIP_L" type="mesh" mesh="LINK_F4_PIP_L" />
                                                            <body name="LINK_F4_DIP_L" pos="0.027 0 0">
                                                                <inertial pos="0.0138132 -0.000331967 5.37266e-05" quat="0.493519 0.494163 0.502438 0.509704" mass="0.00525722" diaginertia="4.32835e-07 3.3084e-07 2.09132e-07" />
                                                                <!-- <joint name="J_F4_DIP_L" pos="0 0 0" axis="0 0 1" limited="true" range="0 1.7" /> -->
                                                                <geom type="mesh" contype="0" conaffinity="0" group="1" rgba="0.752941 0.752941 0.752941 1" mesh="LINK_F4_DIP_L" />
                                                            </body>
                                                        </body>
                                                    </body>
                                                </body>
                                            </body>
                                        </body>
                                    </body>
                                </body>
                            </body>
                        </body>
                    </body>
                    <!-- <body childclass="Arm" name="LINK_SHOULDER_R1" pos="0 -0.16 0.4" quat="0.499998 -0.5 0.5 0.500002"> -->
                    <body childclass="Arm" name="LINK_SHOULDER_R1" pos="0 -0.18 0.4" quat="0.499998 -0.5 0.5 0.500002">
                        <inertial pos="-2e-05 0.002185 -0.063744" quat="0.707059 -0.00821607 0.00821607 0.707059" mass="1.6989" diaginertia="0.00312856 0.002257 0.00209544" />
                        <joint name="J_SHOULDER_R1" pos="0 0 0" axis="0 0 1" limited="true" range="-3.6652 1.5708" />
                        <geom type="mesh" group="1" rgba="0.752941 0.752941 0.752941 1" mesh="LINK_SHOULDER_R1" />
                        <!-- <body name="LINK_SHOULDER_R2" pos="0 0 -0.07" quat="0.707105 0.707108 0 0"> -->
                        <body name="LINK_SHOULDER_R2" pos="0 0 -0.0465" quat="0.707105 0.707108 0 0">
                            <inertial pos="0.10988 0.000196 0.001131" quat="0.510873 0.483195 0.47866 0.525753" mass="1.8095" diaginertia="0.00373127 0.00355104 0.00156769" />
                            <joint name="J_SHOULDER_R2" pos="0 0 0" axis="0 0 1" limited="true" range="-2.2689 0.261799" />
                            <geom type="mesh" group="1" rgba="0.752941 0.752941 0.752941 1" mesh="LINK_SHOULDER_R2" />
                            <body name="LINK_SHOULDER_R3" pos="0.1684 0 0" quat="0.707105 0 0.707108 0">
                                <inertial pos="-0.000217 1.9e-05 0.060151" quat="0.713652 0.00131979 0.00216755 0.700496" mass="1.7403" diaginertia="0.00229102 0.002237 0.00142798" />
                                <joint name="J_SHOULDER_R3" pos="0 0 0" axis="0 0 1" limited="true" range="-2.618 2.618" />
                                <geom quat="0.707105 0 0 0.707108" type="mesh" group="1" rgba="0.752941 0.752941 0.752941 1" mesh="LINK_SHOULDER_R3" />
                                <body name="LINK_ELBOW_R1" pos="0 0 0.1426" quat="0.499998 -0.5 -0.5 -0.500002">
                                    <inertial pos="0.070289 -0.000162 0.000211" quat="0.500864 0.504451 0.483424 0.510848" mass="1.4588" diaginertia="0.00254623 0.00249371 0.00114006" />
                                    <joint name="J_ELBOW_R1" pos="0 0 0" axis="0 0 1" limited="true" range="-1.7453 0" />
                                    <site name="E_R_SITE" pos="0 0 0" size="0.002" rgba="1 0 0 1"/>
                                    <geom quat="-3.67321e-06 1 0 0" type="mesh" group="1" rgba="0.752941 0.752941 0.752941 1" mesh="LINK_ELBOW_R1" />
                                    <body name="LINK_ELBOW_R2" pos="0.124 0 0" quat="0.499998 0.5 0.500002 0.5">
                                        <inertial pos="-0.000365 -0.00147 0.101648" quat="0.676823 -0.00305844 0.00323688 0.736133" mass="1.37062" diaginertia="0.00696362 0.00636479 0.00179459" />
                                        <!-- <joint name="J_ELBOW_R2" pos="0 0 0" axis="0 0 1" limited="true" range="-2.618 2.618" /> -->
                                        <geom type="mesh" group="1" rgba="0.752941 0.752941 0.752941 1" mesh="LINK_ELBOW_R2" />
                                        <body name="LINK_WRIST_R1" pos="0 0 0.1885" quat="0.707105 0 -0.707108 0">
                                            <inertial pos="4e-06 -0.001549 -0.001352" mass="0.021797" diaginertia="1.2e-05 7e-06 6e-06" />
                                            <!-- <joint name="J_WRIST_R1" pos="0 0 0" axis="0 0 1" limited="true" range="-1.0472 1.0472" /> -->
                                            <geom type="mesh" contype="0" conaffinity="0" group="1" rgba="0.752941 0.752941 0.752941 1" mesh="LINK_WRIST_R1" />
                                            <body name="LINK_WRIST_R2" pos="0 0 0" quat="0.707105 -0.707108 0 0">
                                                <inertial pos="0.108985 -6e-05 0.005756" quat="0.515738 0.507907 0.481793 0.493883" mass="1.32955" diaginertia="0.00587773 0.00455711 0.00166116" />
                                                <site name="W_R_SITE" pos="0 0 0" size="0.002" rgba="0 1 0 1"/>
                                                <!-- <joint name="J_WRIST_R2" pos="0 0 0" axis="0 0 1" limited="true" range="-0.7854 0.7854" /> -->
                                                <geom quat="0.707105 0.707108 0 0" type="mesh" contype="0" conaffinity="0" group="1" rgba="0.752941 0.752941 0.752941 1" mesh="LINK_WRIST_R2" />
                                                <body name="LINK_PALM_R" pos="0.039 -0.0065 -0.0027" euler="0 0 0">
                                                    <site name="LINK_PALM_R"/>
                                                    <site name="LINK_PALM_LIDAR_R0" type="box" size="0.002 0.002 0.002" rgba="0 0 1 1" pos="0.056394 0.0024896 0.0201" />
                                                    <site name="LINK_PALM_PROXIMITY_R0" type="cylinder" size="0.00152 0.0005" rgba="0 1 1 1" pos="0.0598016 0.0022657 0.0201"/>
                                                    <geom type="mesh" contype="0" conaffinity="0" group="1" rgba="0.752941 0.752941 0.752941 1" pos="0.094391 0.02376 0" quat="-3.67265e-06 0.999848 0.0174526 -6.4107e-08" mesh="LINK_F3_MPR_R" />
                                                    <geom type="mesh" contype="0" conaffinity="0" group="1" rgba="0.752941 0.752941 0.752941 1" pos="0.085272 0.045516 0" quat="-3.67097e-06 0.999391 0.0348994 -1.28193e-07" mesh="LINK_F4_MPR_R" />
                                                    <geom contype="1" group="1" condim="4" rgba="0.752941 0.752941 0.752941 1" conaffinity="0" name="LINK_PALM_R" type="mesh" mesh="LINK_PALM_R"/>
                                                    <body name="LINK_F0_CMR_R" pos="0.038644 -0.020454 0.0092393" quat="0.65328 0.653282 -0.270599 -0.270598">
                                                        <inertial pos="0.00283749 0.000223308 0.00103973" quat="0.522246 0.478861 0.477734 0.519348" mass="0.00559568" diaginertia="4.03214e-07 3.22464e-07 2.85515e-07" />
                                                        <!-- <joint name="J_F0_CMR_R" pos="0 0 0" axis="0 0 1" limited="true" range="0 1.5708" /> -->
                                                        <geom contype="1" conaffinity="1" group="1" condim="4" rgba="0.752941 0.752941 0.752941 1" name="LINK_F0_CMR_R" type="mesh" mesh="LINK_F0_CMR_R" />
                                                        <body name="LINK_F0_CMP_R" pos="0.01 0 0" quat="0.707105 -0.707108 0 0">
                                                            <inertial pos="0.0178949 -0.00174704 1.51001e-05" quat="0.494457 0.490367 0.50584 0.509095" mass="0.0186139" diaginertia="4.39046e-06 4.15077e-06 1.68756e-06" />
                                                            <!-- <joint name="J_F0_CMP_R" pos="0 0 0" axis="0 0 1" limited="true" range="-0.349066 1.22117" /> -->
                                                            <geom contype="1" group="1" condim="4" rgba="0.752941 0.752941 0.752941 1" conaffinity="0" name="LINK_F0_CMP_R" type="mesh" mesh="LINK_F0_CMP_R" />
                                                            <body name="LINK_F0_MPP_R" pos="0.045 0 0">
                                                                <inertial pos="0.0134858 -0.00194755 3.70272e-05" quat="0.475399 0.537291 0.508262 0.476428" mass="0.0068671" diaginertia="7.44252e-07 6.07436e-07 3.89101e-07" />
                                                                <!-- <joint name="J_F0_MPP_R" pos="0 0 0" axis="0 0 1" limited="true" range="0 1.5708" /> -->
                                                                <geom contype="1" conaffinity="1" group="1" condim="4" rgba="0.752941 0.752941 0.752941 1" name="LINK_F0_MPP_R" type="mesh" mesh="LINK_F0_MPP_R" />
                                                                <body name="LINK_F0_IP_R" pos="0.027 0 0">
                                                                    <inertial pos="0.0125007 -0.00223535 -0.00038541" quat="0.507073 0.469661 0.4922 0.529183" mass="0.00512358" diaginertia="5.87347e-07 3.93558e-07 3.08372e-07" />
                                                                    <!-- <joint name="J_F0_IP_R" pos="0 0 0" axis="0 0 1" limited="true" range="0 1.7" /> -->
                                                                    <geom type="mesh" contype="0" conaffinity="0" group="1" rgba="0.752941 0.752941 0.752941 1" mesh="LINK_F0_IP_R" />
                                                                </body>
                                                            </body>
                                                        </body>
                                                    </body>
                                                    <body name="LINK_F1_MPR_R" pos="0.094 -0.0245 0" quat="-3.67321e-06 1 0 0">
                                                        <inertial pos="0.00325879 0.000161013 0.00112841" quat="0.512578 0.506716 0.489597 0.490711" mass="0.00500155" diaginertia="3.46608e-07 2.56011e-07 2.3013e-07" />
                                                        <!-- <joint name="J_F1_MPR_R" pos="0 0 0" axis="0 0 1" limited="true" range="-0.349066 0.349066" /> -->
                                                        <geom contype="1" conaffinity="1" group="1" condim="4" rgba="0.752941 0.752941 0.752941 1" name="LINK_F1_MPR_R" type="mesh" mesh="LINK_F1_MPR_R" />
                                                        <body name="LINK_F1_MPP_R" pos="0.01 0 0" quat="0.707105 -0.707108 0 0">
                                                            <inertial pos="0.0170176 -0.0010274 -3.54625e-05" quat="0.00293599 0.701784 0.00182744 0.712381" mass="0.0105685" diaginertia="1.98527e-06 1.88784e-06 4.99044e-07" />
                                                            <!-- <joint name="J_F1_MPP_R" pos="0 0 0" axis="0 0 1" limited="true" range="0 1.5708" /> -->
                                                            <geom contype="1" group="1" condim="4" rgba="0.752941 0.752941 0.752941 1" conaffinity="0" name="LINK_F1_MPP_R" type="mesh" mesh="LINK_F1_MPP_R" />
                                                            <body name="LINK_F1_PIP_R" pos="0.04 0 0">
                                                                <inertial pos="0.0135605 -0.00133924 4.55527e-05" quat="0.24806 0.693037 0.233958 0.635161" mass="0.00541254" diaginertia="4.91119e-07 4.82284e-07 1.96332e-07" />
                                                                <!-- <joint name="J_F1_PIP_R" pos="0 0 0" axis="0 0 1" limited="true" range="0 1.5708" /> -->
                                                                <geom contype="1" conaffinity="1" group="1" condim="4" rgba="0.752941 0.752941 0.752941 1" name="LINK_F1_PIP_R" type="mesh" mesh="LINK_F1_PIP_R" />
                                                                <body name="LINK_F1_DIP_R" pos="0.027 0 0">
                                                                    <inertial pos="0.0145494 -0.000408056 -0.000377853" quat="0.503609 0.47665 0.497905 0.520839" mass="0.00490823" diaginertia="4.18002e-07 3.17272e-07 1.97971e-07" />
                                                                    <!-- <joint name="J_F1_DIP_R" pos="0 0 0" axis="0 0 1" limited="true" range="0 1.7" /> -->
                                                                    <geom type="mesh" contype="0" conaffinity="0" group="1" rgba="0.752941 0.752941 0.752941 1" mesh="LINK_F1_DIP_R" />
                                                                </body>
                                                            </body>
                                                        </body>
                                                    </body>
                                                    <body name="LINK_F2_MPR_R" pos="0.1 0 0" quat="-3.67321e-06 1 0 0">
                                                        <inertial pos="0.00325879 0.000161013 0.00112841" quat="0.512578 0.506716 0.489597 0.490711" mass="0.00500155" diaginertia="3.46608e-07 2.56011e-07 2.3013e-07" />
                                                        <!-- <joint name="J_F2_MPR_R" pos="0 0 0" axis="0 0 1" limited="true" range="-0.349066 0.349066" /> -->
                                                        <geom contype="1" conaffinity="1" group="1" condim="4" rgba="0.752941 0.752941 0.752941 1" name="LINK_F2_MPR_R" type="mesh" mesh="LINK_F2_MPR_R" />
                                                        <body name="LINK_F2_MPP_R" pos="0.01 0 0" quat="0.707105 -0.707108 0 0">
                                                            <inertial pos="0.0170176 -0.0010274 -3.54625e-05" quat="0.00293599 0.701784 0.00182744 0.712381" mass="0.0105685" diaginertia="1.98527e-06 1.88784e-06 4.99044e-07" />
                                                            <!-- <joint name="J_F2_MPP_R" pos="0 0 0" axis="0 0 1" limited="true" range="0 1.5708" /> -->
                                                            <geom contype="1" group="1" condim="4" rgba="0.752941 0.752941 0.752941 1" conaffinity="0" name="LINK_F2_MPP_R" type="mesh" mesh="LINK_F2_MPP_R" />
                                                            <body name="LINK_F2_PIP_R" pos="0.04 0 0">
                                                                <inertial pos="0.0135605 -0.00133924 4.55527e-05" quat="0.24806 0.693037 0.233958 0.635161" mass="0.00541254" diaginertia="4.91119e-07 4.82284e-07 1.96332e-07" />
                                                                <!-- <joint name="J_F2_PIP_R" pos="0 0 0" axis="0 0 1" limited="true" range="0 1.5708" /> -->
                                                                <geom contype="1" conaffinity="1" group="1" condim="4" rgba="0.752941 0.752941 0.752941 1" name="LINK_F2_PIP_R" type="mesh" mesh="LINK_F2_PIP_R" />
                                                                <body name="LINK_F2_DIP_R" pos="0.027 0 0">
                                                                    <inertial pos="0.0145494 -0.000408056 -0.000377853" quat="0.503609 0.47665 0.497905 0.520839" mass="0.00490823" diaginertia="4.18002e-07 3.17272e-07 1.97971e-07" />
                                                                    <!-- <joint name="J_F2_DIP_R" pos="0 0 0" axis="0 0 1" limited="true" range="0 1.7" /> -->
                                                                    <geom type="mesh" contype="0" conaffinity="0" group="1" rgba="0.752941 0.752941 0.752941 1" mesh="LINK_F2_DIP_R" />
                                                                </body>
                                                            </body>
                                                        </body>
                                                    </body>
                                                    <body name="LINK_F3_MPP_R" pos="0.104385 0.024109 0" quat="0.706998 0.707 0.0123409 0.0123408">
                                                        <inertial pos="0.0183676 -0.00112703 2.96568e-05" quat="0.00403143 0.710887 0.00437976 0.703281" mass="0.00947234" diaginertia="1.97212e-06 1.89237e-06 4.63126e-07" />
                                                        <!-- <joint name="J_F3_MPP_R" pos="0 0 0" axis="0 0 1" limited="true" range="0 1.5708" /> -->
                                                        <geom contype="1" conaffinity="1" group="1" condim="4" rgba="0.752941 0.752941 0.752941 1" name="LINK_F3_MPP_R" type="mesh" mesh="LINK_F3_MPP_R" />
                                                        <body name="LINK_F3_PIP_R" pos="0.04 0 0">
                                                            <inertial pos="0.0120056 -0.00124466 8.56618e-05" quat="0.239898 0.661047 0.239175 0.669523" mass="0.00492442" diaginertia="5.05359e-07 5.0045e-07 1.96299e-07" />
                                                            <!-- <joint name="J_F3_PIP_R" pos="0 0 0" axis="0 0 1" limited="true" range="0 1.5708" /> -->
                                                            <geom contype="1" conaffinity="1" group="1" condim="4" rgba="0.752941 0.752941 0.752941 1" name="LINK_F3_PIP_R" type="mesh" mesh="LINK_F3_PIP_R" />
                                                            <body name="LINK_F3_DIP_R" pos="0.027 0 0">
                                                                <inertial pos="0.0138134 -0.00033209 5.36647e-05" quat="0.493517 0.494164 0.502448 0.509695" mass="0.0052572" diaginertia="4.32842e-07 3.30856e-07 2.09125e-07" />
                                                                <!-- <joint name="J_F3_DIP_R" pos="0 0 0" axis="0 0 1" limited="true" range="0 1.7" /> -->
                                                                <geom type="mesh" contype="0" conaffinity="0" group="1" rgba="0.752941 0.752941 0.752941 1" mesh="LINK_F3_DIP_R" />
                                                            </body>
                                                        </body>
                                                    </body>
                                                    <body name="LINK_F4_MPP_R" pos="0.0952476 0.0462136 0" quat="0.706675 0.706677 0.0246777 0.0246776">
                                                        <inertial pos="0.0183676 -0.00112703 2.96567e-05" quat="0.00403109 0.710887 0.00437941 0.703281" mass="0.00947234" diaginertia="1.97212e-06 1.89237e-06 4.63127e-07" />
                                                        <!-- <joint name="J_F4_MPP_R" pos="0 0 0" axis="0 0 1" limited="true" range="0 1.5708" /> -->
                                                        <geom contype="1" conaffinity="1" group="1" condim="4" rgba="0.752941 0.752941 0.752941 1" name="LINK_F4_MPP_R" type="mesh" mesh="LINK_F4_MPP_R" />
                                                        <body name="LINK_F4_PIP_R" pos="0.04 0 0">
                                                            <inertial pos="0.0120056 -0.00124466 8.56621e-05" quat="0.239897 0.661047 0.239174 0.669523" mass="0.00492442" diaginertia="5.05359e-07 5.0045e-07 1.96299e-07" />
                                                            <!-- <joint name="J_F4_PIP_R" pos="0 0 0" axis="0 0 1" limited="true" range="0 1.5708" /> -->
                                                            <geom contype="1" conaffinity="1" group="1" condim="4" rgba="0.752941 0.752941 0.752941 1" name="LINK_F4_PIP_R" type="mesh" mesh="LINK_F4_PIP_R" />
                                                            <body name="LINK_F4_DIP_R" pos="0.027 0 0">
                                                                <inertial pos="0.0138134 -0.000332096 5.36911e-05" quat="0.493518 0.494163 0.502448 0.509695" mass="0.00525719" diaginertia="4.32842e-07 3.30855e-07 2.09126e-07" />
                                                                <!-- <joint name="J_F4_DIP_R" pos="0 0 0" axis="0 0 1" limited="true" range="0 1.7" /> -->
                                                                <geom type="mesh" contype="0" conaffinity="0" group="1" rgba="0.752941 0.752941 0.752941 1" mesh="LINK_F4_DIP_R" />
                                                            </body>
                                                        </body>
                                                    </body>
                                                </body>
                                            </body>
                                        </body>
                                    </body>
                                </body>
                            </body>
                        </body>
                    </body>
                </body>
            </body>
            <site name="E_L_SITE_Target" pos="0.34 0.302 0.74" size="0.002" rgba="1 1 0 1"/>
            <site name="E_R_SITE_Target" pos="0.34 -0.302 0.74" size="0.002" rgba="1 0 0 1"/>
        </body>
    </worldbody>
    <!-- <equality>
        <weld body1="LINK_BASE" body2="mobile_base_mocap" solref="0.002 1" solimp="0.999 0.999 0.01"/>
    </equality> -->

    <sensor>
        <gyro name="xman_gyro" site="imu_site"/>
        <accelerometer name="xman_accelerometer" site="imu_site"/>
        
        <velocimeter name="head_site_linvel" site="H_SITE"/>

        <velocimeter name="elbowl_site_linvel" site="E_L_SITE"/>
        <velocimeter name="wristl_site_linvel" site="W_L_SITE"/>
        <velocimeter name="elbowr_site_linvel" site="E_R_SITE"/>
        <velocimeter name="wristr_site_linvel" site="W_R_SITE"/>

        <gyro name="elbowl_site_angvel" site="E_L_SITE"/>
        <gyro name="wristl_site_angvel" site="W_L_SITE"/>
        <gyro name="elbowr_site_angvel" site="E_R_SITE"/>
        <gyro name="wristr_site_angvel" site="W_R_SITE"/>
    </sensor>

    <contact>
        <pair geom1="floor" geom2="GEOM_MED_WHEEL_L" condim="3" friction="0.07 0.07 0 0.005 0.005" />
        <pair geom1="floor" geom2="GEOM_MED_WHEEL_R" condim="3" friction="0.07 0.07 0 0.005 0.005" />
        <pair geom1="floor" geom2="GEOM_LAT_WHEEL_L" condim="3" friction="0.8 0.8 0 0.005 0.005" />
        <pair geom1="floor" geom2="GEOM_LAT_WHEEL_R" condim="3" friction="0.8 0.8 0 0.005 0.005" />
    </contact>


</mujoco>
